c_path,result,error,status,execution_time,processed_time
TPDB_YES/Benghazi_nondet_true-termination.c,MAYBE,,success,1.9192347526550293,2025-05-23 03:39:45
TPDB_YES/svcomp_openbsd_cstrpbrk_alloca.c,ERROR,"[616439] Failed to execute script irankfinder
Traceback (most recent call last):
  File ""irankfinder.py"", line 190, in parse_file
  File ""genericparser/__init__.py"", line 109, in parse
  File ""genericparser/Parser_c.py"", line 25, in parse
  File ""genericparser/Parser_koat.py"", line 25, in parse_string
  File ""lark/lark.py"", line 197, in parse
  File ""lark/parser_frontends.py"", line 137, in parse
  File ""lark/parsers/xearley.py"", line 143, in parse
lark.common.ParseError: Unexpected end of input! Expecting a terminal of: ['__LPAR']

The above exception was the direct cause of the following exception:

Traceback (most recent call last):
  File ""irankfinder.py"", line 374, in <module>
  File ""irankfinder.py"", line 205, in launch
  File ""irankfinder.py"", line 197, in parse_file
Exception
",failed,0.490659236907959,2025-05-23 03:39:45
TPDB_YES/svcomp_strreplace_alloca.c,ERROR,"[616452] Failed to execute script irankfinder
Traceback (most recent call last):
  File ""irankfinder.py"", line 190, in parse_file
  File ""genericparser/__init__.py"", line 109, in parse
  File ""genericparser/Parser_c.py"", line 25, in parse
  File ""genericparser/Parser_koat.py"", line 25, in parse_string
  File ""lark/lark.py"", line 197, in parse
  File ""lark/parser_frontends.py"", line 137, in parse
  File ""lark/parsers/xearley.py"", line 143, in parse
lark.common.ParseError: Unexpected end of input! Expecting a terminal of: ['__LPAR']

The above exception was the direct cause of the following exception:

Traceback (most recent call last):
  File ""irankfinder.py"", line 374, in <module>
  File ""irankfinder.py"", line 205, in launch
  File ""irankfinder.py"", line 197, in parse_file
Exception
",failed,0.4928412437438965,2025-05-23 03:39:46
TPDB_YES/ChenFlurMukhopadhyay-SAS2012-Ex4.01_true-termination.c,MAYBE,,success,2.106675386428833,2025-05-23 03:39:48
TPDB_YES/ChenFlurMukhopadhyay-SAS2012-Ex2.10_true-termination.c,YES,,success,1.7392487525939941,2025-05-23 03:39:49
TPDB_YES/AliasDarteFeautrierGonnord-SAS2010-speedpldi4_true-termination.c,MAYBE,,success,1.361990213394165,2025-05-23 03:39:51
TPDB_YES/ex3.c,ERROR,"[616507] Failed to execute script irankfinder
Traceback (most recent call last):
  File ""irankfinder.py"", line 190, in parse_file
  File ""genericparser/__init__.py"", line 109, in parse
  File ""genericparser/Parser_c.py"", line 21, in parse
Exception: b'Cannot use ""-eager-inline"" with a cyclic call hierarchy!\n'

The above exception was the direct cause of the following exception:

Traceback (most recent call last):
  File ""irankfinder.py"", line 374, in <module>
  File ""irankfinder.py"", line 205, in launch
  File ""irankfinder.py"", line 197, in parse_file
Exception
",failed,0.33170342445373535,2025-05-23 03:39:51
TPDB_YES/CookSeeZuleger-TACAS2013-Fig8b_true-termination.c,MAYBE,,success,1.7987148761749268,2025-05-23 03:39:53
TPDB_YES/svcomp_c.08.c,MAYBE,,success,2.4853241443634033,2025-05-23 03:39:55
TPDB_YES/AliasDarteFeautrierGonnord-SAS2010-counterex1b_true-termination.c,MAYBE,,success,6.151113748550415,2025-05-23 03:40:02
TPDB_YES/nondet_ll_traverse_rec.c,ERROR,"[616564] Failed to execute script irankfinder
Traceback (most recent call last):
  File ""irankfinder.py"", line 190, in parse_file
  File ""genericparser/__init__.py"", line 109, in parse
  File ""genericparser/Parser_c.py"", line 25, in parse
  File ""genericparser/Parser_koat.py"", line 25, in parse_string
  File ""lark/lark.py"", line 197, in parse
  File ""lark/parser_frontends.py"", line 137, in parse
  File ""lark/parsers/xearley.py"", line 143, in parse
lark.common.ParseError: Unexpected end of input! Expecting a terminal of: ['__LPAR']

The above exception was the direct cause of the following exception:

Traceback (most recent call last):
  File ""irankfinder.py"", line 374, in <module>
  File ""irankfinder.py"", line 205, in launch
  File ""irankfinder.py"", line 197, in parse_file
Exception
",failed,0.4811432361602783,2025-05-23 03:40:02
TPDB_YES/NestedRecursion_1d_true-termination.c,ERROR,"[616577] Failed to execute script irankfinder
Traceback (most recent call last):
  File ""irankfinder.py"", line 190, in parse_file
  File ""genericparser/__init__.py"", line 109, in parse
  File ""genericparser/Parser_c.py"", line 21, in parse
Exception: b'Cannot use ""-eager-inline"" with a cyclic call hierarchy!\n'

The above exception was the direct cause of the following exception:

Traceback (most recent call last):
  File ""irankfinder.py"", line 374, in <module>
  File ""irankfinder.py"", line 205, in launch
  File ""irankfinder.py"", line 197, in parse_file
Exception
",failed,0.4524955749511719,2025-05-23 03:40:03
TPDB_YES/Fibonacci01_true-unreach-call.c,ERROR,"[616591] Failed to execute script irankfinder
Traceback (most recent call last):
  File ""irankfinder.py"", line 190, in parse_file
  File ""genericparser/__init__.py"", line 109, in parse
  File ""genericparser/Parser_c.py"", line 21, in parse
Exception: b'Cannot use ""-eager-inline"" with a cyclic call hierarchy!\n'

The above exception was the direct cause of the following exception:

Traceback (most recent call last):
  File ""irankfinder.py"", line 374, in <module>
  File ""irankfinder.py"", line 205, in launch
  File ""irankfinder.py"", line 197, in parse_file
Exception
",failed,0.40873241424560547,2025-05-23 03:40:03
TPDB_YES/WhileDecr.c,YES,,success,1.2346816062927246,2025-05-23 03:40:04
TPDB_YES/PodelskiRybalchenko-LICS2004-Fig2_true-termination.c,MAYBE,,success,2.776458978652954,2025-05-23 03:40:07
TPDB_YES/svcomp_cstrlen_true-termination.c,ERROR,"[616633] Failed to execute script irankfinder
Traceback (most recent call last):
  File ""irankfinder.py"", line 190, in parse_file
  File ""genericparser/__init__.py"", line 109, in parse
  File ""genericparser/Parser_c.py"", line 25, in parse
  File ""genericparser/Parser_koat.py"", line 25, in parse_string
  File ""lark/lark.py"", line 197, in parse
  File ""lark/parser_frontends.py"", line 137, in parse
  File ""lark/parsers/xearley.py"", line 143, in parse
lark.common.ParseError: Unexpected end of input! Expecting a terminal of: ['__LPAR']

The above exception was the direct cause of the following exception:

Traceback (most recent call last):
  File ""irankfinder.py"", line 374, in <module>
  File ""irankfinder.py"", line 205, in launch
  File ""irankfinder.py"", line 197, in parse_file
Exception
",failed,0.35225653648376465,2025-05-23 03:40:07
TPDB_YES/AliasDarteFeautrierGonnord-SAS2010-rsd_true-termination.c,MAYBE,,success,2.545973300933838,2025-05-23 03:40:10
TPDB_YES/GCD3.c,YES,,success,3.944690704345703,2025-05-23 03:40:14
TPDB_YES/ChawdharyCookGulwaniSagivYang-ESOP2008-aaron6_true-termination.c,MAYBE,,success,8.4492666721344,2025-05-23 03:40:22
TPDB_YES/ChenFlurMukhopadhyay-SAS2012-Ex2.22_true-termination.c,MAYBE,,success,1.4569125175476074,2025-05-23 03:40:24
TPDB_YES/rec_strlen.c,ERROR,"[616702] Failed to execute script irankfinder
Traceback (most recent call last):
  File ""irankfinder.py"", line 190, in parse_file
  File ""genericparser/__init__.py"", line 109, in parse
  File ""genericparser/Parser_c.py"", line 25, in parse
  File ""genericparser/Parser_koat.py"", line 25, in parse_string
  File ""lark/lark.py"", line 197, in parse
  File ""lark/parser_frontends.py"", line 137, in parse
  File ""lark/parsers/xearley.py"", line 143, in parse
lark.common.ParseError: Unexpected end of input! Expecting a terminal of: ['__LPAR']

The above exception was the direct cause of the following exception:

Traceback (most recent call last):
  File ""irankfinder.py"", line 374, in <module>
  File ""irankfinder.py"", line 205, in launch
  File ""irankfinder.py"", line 197, in parse_file
Exception
",failed,0.3502187728881836,2025-05-23 03:40:24
TPDB_YES/Avery-FLOPS2006-Table1_true-termination.c,YES,,success,2.115312099456787,2025-05-23 03:40:26
TPDB_YES/svcomp_LarrazOliverasRodriguez-CarbonellRubio-2013FMCAD-Fig1_true-alloca.c,ERROR,"[616730] Failed to execute script irankfinder
Traceback (most recent call last):
  File ""irankfinder.py"", line 190, in parse_file
  File ""genericparser/__init__.py"", line 109, in parse
  File ""genericparser/Parser_c.py"", line 25, in parse
  File ""genericparser/Parser_koat.py"", line 25, in parse_string
  File ""lark/lark.py"", line 197, in parse
  File ""lark/parser_frontends.py"", line 137, in parse
  File ""lark/parsers/xearley.py"", line 143, in parse
lark.common.ParseError: Unexpected end of input! Expecting a terminal of: ['__LPAR']

The above exception was the direct cause of the following exception:

Traceback (most recent call last):
  File ""irankfinder.py"", line 374, in <module>
  File ""irankfinder.py"", line 205, in launch
  File ""irankfinder.py"", line 197, in parse_file
Exception
",failed,0.34787988662719727,2025-05-23 03:40:27
TPDB_YES/EvenOdd01_true-unreach-call_true-termination.c,ERROR,"[616743] Failed to execute script irankfinder
Traceback (most recent call last):
  File ""irankfinder.py"", line 190, in parse_file
  File ""genericparser/__init__.py"", line 109, in parse
  File ""genericparser/Parser_c.py"", line 21, in parse
Exception: b'Cannot use ""-eager-inline"" with a cyclic call hierarchy!\n'

The above exception was the direct cause of the following exception:

Traceback (most recent call last):
  File ""irankfinder.py"", line 374, in <module>
  File ""irankfinder.py"", line 205, in launch
  File ""irankfinder.py"", line 197, in parse_file
Exception
",failed,0.34179139137268066,2025-05-23 03:40:27
TPDB_YES/rec_counter1.c,ERROR,"[616757] Failed to execute script irankfinder
Traceback (most recent call last):
  File ""irankfinder.py"", line 190, in parse_file
  File ""genericparser/__init__.py"", line 109, in parse
  File ""genericparser/Parser_c.py"", line 21, in parse
Exception: b'Cannot use ""-eager-inline"" with a cyclic call hierarchy!\n'

The above exception was the direct cause of the following exception:

Traceback (most recent call last):
  File ""irankfinder.py"", line 374, in <module>
  File ""irankfinder.py"", line 205, in launch
  File ""irankfinder.py"", line 197, in parse_file
Exception
",failed,0.3354029655456543,2025-05-23 03:40:27
TPDB_YES/svcomp_Ackermann01_true-unreach-call_modified_modified.c,ERROR,"[616771] Failed to execute script irankfinder
Traceback (most recent call last):
  File ""irankfinder.py"", line 190, in parse_file
  File ""genericparser/__init__.py"", line 109, in parse
  File ""genericparser/Parser_c.py"", line 21, in parse
Exception: b'Cannot use ""-eager-inline"" with a cyclic call hierarchy!\n'

The above exception was the direct cause of the following exception:

Traceback (most recent call last):
  File ""irankfinder.py"", line 374, in <module>
  File ""irankfinder.py"", line 205, in launch
  File ""irankfinder.py"", line 197, in parse_file
Exception
",failed,0.35150623321533203,2025-05-23 03:40:28
TPDB_YES/svcomp_Urban_true-alloca.c,ERROR,"[616785] Failed to execute script irankfinder
Traceback (most recent call last):
  File ""irankfinder.py"", line 190, in parse_file
  File ""genericparser/__init__.py"", line 109, in parse
  File ""genericparser/Parser_c.py"", line 25, in parse
  File ""genericparser/Parser_koat.py"", line 25, in parse_string
  File ""lark/lark.py"", line 197, in parse
  File ""lark/parser_frontends.py"", line 137, in parse
  File ""lark/parsers/xearley.py"", line 143, in parse
lark.common.ParseError: Unexpected end of input! Expecting a terminal of: ['__LPAR']

The above exception was the direct cause of the following exception:

Traceback (most recent call last):
  File ""irankfinder.py"", line 374, in <module>
  File ""irankfinder.py"", line 205, in launch
  File ""irankfinder.py"", line 197, in parse_file
Exception
",failed,0.35642027854919434,2025-05-23 03:40:28
TPDB_YES/desc_ll_search_existing.c,ERROR,"[616798] Failed to execute script irankfinder
Traceback (most recent call last):
  File ""irankfinder.py"", line 190, in parse_file
  File ""genericparser/__init__.py"", line 109, in parse
  File ""genericparser/Parser_c.py"", line 25, in parse
  File ""genericparser/Parser_koat.py"", line 25, in parse_string
  File ""lark/lark.py"", line 197, in parse
  File ""lark/parser_frontends.py"", line 137, in parse
  File ""lark/parsers/xearley.py"", line 143, in parse
lark.common.ParseError: Unexpected end of input! Expecting a terminal of: ['__LPAR']

The above exception was the direct cause of the following exception:

Traceback (most recent call last):
  File ""irankfinder.py"", line 374, in <module>
  File ""irankfinder.py"", line 205, in launch
  File ""irankfinder.py"", line 197, in parse_file
Exception
",failed,0.3497910499572754,2025-05-23 03:40:28
TPDB_YES/AliasDarteFeautrierGonnord-SAS2010-cousot9_true-termination.c,MAYBE,,success,1.4276432991027832,2025-05-23 03:40:30
TPDB_YES/nondet_ll_traverse.c,ERROR,"[616825] Failed to execute script irankfinder
Traceback (most recent call last):
  File ""irankfinder.py"", line 190, in parse_file
  File ""genericparser/__init__.py"", line 109, in parse
  File ""genericparser/Parser_c.py"", line 25, in parse
  File ""genericparser/Parser_koat.py"", line 25, in parse_string
  File ""lark/lark.py"", line 197, in parse
  File ""lark/parser_frontends.py"", line 137, in parse
  File ""lark/parsers/xearley.py"", line 143, in parse
lark.common.ParseError: Unexpected end of input! Expecting a terminal of: ['__LPAR']

The above exception was the direct cause of the following exception:

Traceback (most recent call last):
  File ""irankfinder.py"", line 374, in <module>
  File ""irankfinder.py"", line 205, in launch
  File ""irankfinder.py"", line 197, in parse_file
Exception
",failed,0.3548445701599121,2025-05-23 03:40:30
TPDB_YES/svcomp_openbsd_cstrncpy_alloca.c,ERROR,"[616838] Failed to execute script irankfinder
Traceback (most recent call last):
  File ""irankfinder.py"", line 190, in parse_file
  File ""genericparser/__init__.py"", line 109, in parse
  File ""genericparser/Parser_c.py"", line 25, in parse
  File ""genericparser/Parser_koat.py"", line 25, in parse_string
  File ""lark/lark.py"", line 197, in parse
  File ""lark/parser_frontends.py"", line 137, in parse
  File ""lark/parsers/xearley.py"", line 143, in parse
lark.common.ParseError: Unexpected end of input! Expecting a terminal of: ['__LPAR']

The above exception was the direct cause of the following exception:

Traceback (most recent call last):
  File ""irankfinder.py"", line 374, in <module>
  File ""irankfinder.py"", line 205, in launch
  File ""irankfinder.py"", line 197, in parse_file
Exception
",failed,0.3525969982147217,2025-05-23 03:40:31
TPDB_YES/nondet_ll_search_zero.c,ERROR,"[616851] Failed to execute script irankfinder
Traceback (most recent call last):
  File ""irankfinder.py"", line 190, in parse_file
  File ""genericparser/__init__.py"", line 109, in parse
  File ""genericparser/Parser_c.py"", line 25, in parse
  File ""genericparser/Parser_koat.py"", line 25, in parse_string
  File ""lark/lark.py"", line 197, in parse
  File ""lark/parser_frontends.py"", line 137, in parse
  File ""lark/parsers/xearley.py"", line 143, in parse
lark.common.ParseError: Unexpected end of input! Expecting a terminal of: ['__LPAR']

The above exception was the direct cause of the following exception:

Traceback (most recent call last):
  File ""irankfinder.py"", line 374, in <module>
  File ""irankfinder.py"", line 205, in launch
  File ""irankfinder.py"", line 197, in parse_file
Exception
",failed,0.4780616760253906,2025-05-23 03:40:31
TPDB_YES/PastaB4.c,YES,,success,1.2434618473052979,2025-05-23 03:40:32
TPDB_YES/PastaB11.c,YES,,success,3.2109382152557373,2025-05-23 03:40:36
TPDB_YES/LarrazOliverasRodriguez-CarbonellRubio-FMCAD2013-Fig1_true-termination.c,MAYBE,,success,5.21535849571228,2025-05-23 03:40:41
TPDB_YES/HeizmannHoenickeLeikePodelski-ATVA2013-Fig5_true-termination.c,MAYBE,,success,1.331590175628662,2025-05-23 03:40:42
TPDB_YES/ChenFlurMukhopadhyay-SAS2012-Ex1.04_true-termination.c,YES,,success,1.1748130321502686,2025-05-23 03:40:43
TPDB_YES/svcomp_mult_array_alloca.c,ERROR,"[616934] Failed to execute script irankfinder
Traceback (most recent call last):
  File ""irankfinder.py"", line 190, in parse_file
  File ""genericparser/__init__.py"", line 109, in parse
  File ""genericparser/Parser_c.py"", line 25, in parse
  File ""genericparser/Parser_koat.py"", line 25, in parse_string
  File ""lark/lark.py"", line 197, in parse
  File ""lark/parser_frontends.py"", line 137, in parse
  File ""lark/parsers/xearley.py"", line 143, in parse
lark.common.ParseError: Unexpected end of input! Expecting a terminal of: ['__LPAR']

The above exception was the direct cause of the following exception:

Traceback (most recent call last):
  File ""irankfinder.py"", line 374, in <module>
  File ""irankfinder.py"", line 205, in launch
  File ""irankfinder.py"", line 197, in parse_file
Exception
",failed,0.35180044174194336,2025-05-23 03:40:44
TPDB_YES/svcomp_ex3a.c,MAYBE,,success,1.454643726348877,2025-05-23 03:40:45
TPDB_YES/BrockschmidtCookFuhs-CAV2013-Fig9a_true-termination.c,MAYBE,,success,2.032195568084717,2025-05-23 03:40:47
TPDB_YES/svcomp_c.07-alloca.c,ERROR,"[616975] Failed to execute script irankfinder
Traceback (most recent call last):
  File ""irankfinder.py"", line 190, in parse_file
  File ""genericparser/__init__.py"", line 109, in parse
  File ""genericparser/Parser_c.py"", line 25, in parse
  File ""genericparser/Parser_koat.py"", line 25, in parse_string
  File ""lark/lark.py"", line 197, in parse
  File ""lark/parser_frontends.py"", line 137, in parse
  File ""lark/parsers/xearley.py"", line 143, in parse
lark.common.ParseError: Unexpected end of input! Expecting a terminal of: ['__LPAR']

The above exception was the direct cause of the following exception:

Traceback (most recent call last):
  File ""irankfinder.py"", line 374, in <module>
  File ""irankfinder.py"", line 205, in launch
  File ""irankfinder.py"", line 197, in parse_file
Exception
",failed,0.35500550270080566,2025-05-23 03:40:48
TPDB_YES/svcomp_java_Nested-alloca.c,ERROR,"[616988] Failed to execute script irankfinder
Traceback (most recent call last):
  File ""irankfinder.py"", line 190, in parse_file
  File ""genericparser/__init__.py"", line 109, in parse
  File ""genericparser/Parser_c.py"", line 25, in parse
  File ""genericparser/Parser_koat.py"", line 25, in parse_string
  File ""lark/lark.py"", line 197, in parse
  File ""lark/parser_frontends.py"", line 137, in parse
  File ""lark/parsers/xearley.py"", line 143, in parse
lark.common.ParseError: Unexpected end of input! Expecting a terminal of: ['__LPAR']

The above exception was the direct cause of the following exception:

Traceback (most recent call last):
  File ""irankfinder.py"", line 374, in <module>
  File ""irankfinder.py"", line 205, in launch
  File ""irankfinder.py"", line 197, in parse_file
Exception
",failed,0.4778306484222412,2025-05-23 03:40:48
TPDB_YES/svcomp_b.06.c,YES,,success,1.965902328491211,2025-05-23 03:40:50
TPDB_YES/Benghazi_true-termination.c,MAYBE,,success,1.256659746170044,2025-05-23 03:40:51
TPDB_YES/svcomp_aviad_true-alloca.c,ERROR,"[617029] Failed to execute script irankfinder
Traceback (most recent call last):
  File ""irankfinder.py"", line 190, in parse_file
  File ""genericparser/__init__.py"", line 109, in parse
  File ""genericparser/Parser_c.py"", line 25, in parse
  File ""genericparser/Parser_koat.py"", line 25, in parse_string
  File ""lark/lark.py"", line 197, in parse
  File ""lark/parser_frontends.py"", line 137, in parse
  File ""lark/parsers/xearley.py"", line 143, in parse
lark.common.ParseError: Unexpected end of input! Expecting a terminal of: ['__LPAR']

The above exception was the direct cause of the following exception:

Traceback (most recent call last):
  File ""irankfinder.py"", line 374, in <module>
  File ""irankfinder.py"", line 205, in launch
  File ""irankfinder.py"", line 197, in parse_file
Exception
",failed,0.4849722385406494,2025-05-23 03:40:52
TPDB_YES/svcomp_cstrncpy_alloca.c,ERROR,"[617042] Failed to execute script irankfinder
Traceback (most recent call last):
  File ""irankfinder.py"", line 190, in parse_file
  File ""genericparser/__init__.py"", line 109, in parse
  File ""genericparser/Parser_c.py"", line 25, in parse
  File ""genericparser/Parser_koat.py"", line 25, in parse_string
  File ""lark/lark.py"", line 197, in parse
  File ""lark/parser_frontends.py"", line 137, in parse
  File ""lark/parsers/xearley.py"", line 143, in parse
lark.common.ParseError: Unexpected end of input! Expecting a terminal of: ['__LPAR']

The above exception was the direct cause of the following exception:

Traceback (most recent call last):
  File ""irankfinder.py"", line 374, in <module>
  File ""irankfinder.py"", line 205, in launch
  File ""irankfinder.py"", line 197, in parse_file
Exception
",failed,0.354933500289917,2025-05-23 03:40:52
TPDB_YES/LeeJonesBen-Amram-POPL2001-Ex6_true-termination.c,ERROR,"[617055] Failed to execute script irankfinder
Traceback (most recent call last):
  File ""irankfinder.py"", line 190, in parse_file
  File ""genericparser/__init__.py"", line 109, in parse
  File ""genericparser/Parser_c.py"", line 21, in parse
Exception: b'Cannot use ""-eager-inline"" with a cyclic call hierarchy!\n'

The above exception was the direct cause of the following exception:

Traceback (most recent call last):
  File ""irankfinder.py"", line 374, in <module>
  File ""irankfinder.py"", line 205, in launch
  File ""irankfinder.py"", line 197, in parse_file
Exception
",failed,0.40454554557800293,2025-05-23 03:40:53
TPDB_YES/PastaB16.c,MAYBE,,success,2.5339062213897705,2025-05-23 03:40:55
TPDB_YES/Cairo_true-termination.c,MAYBE,,success,1.2590088844299316,2025-05-23 03:40:56
TPDB_YES/svcomp_java_Break.c,MAYBE,,success,0.7526164054870605,2025-05-23 03:40:57
TPDB_YES/svcomp_b.09_assume.c,MAYBE,,success,2.4916739463806152,2025-05-23 03:41:00
TPDB_YES/MinusUserDefined.c,MAYBE,,success,4.768682956695557,2025-05-23 03:41:04
TPDB_YES/HeizmannHoenickeLeikePodelski-ATVA2013-Fig6_true-termination.c,YES,,success,2.2406680583953857,2025-05-23 03:41:07
TPDB_YES/svcomp_a.07-alloca.c,ERROR,"[617153] Failed to execute script irankfinder
Traceback (most recent call last):
  File ""irankfinder.py"", line 190, in parse_file
  File ""genericparser/__init__.py"", line 109, in parse
  File ""genericparser/Parser_c.py"", line 25, in parse
  File ""genericparser/Parser_koat.py"", line 25, in parse_string
  File ""lark/lark.py"", line 197, in parse
  File ""lark/parser_frontends.py"", line 137, in parse
  File ""lark/parsers/xearley.py"", line 143, in parse
lark.common.ParseError: Unexpected end of input! Expecting a terminal of: ['__LPAR']

The above exception was the direct cause of the following exception:

Traceback (most recent call last):
  File ""irankfinder.py"", line 374, in <module>
  File ""irankfinder.py"", line 205, in launch
  File ""irankfinder.py"", line 197, in parse_file
Exception
",failed,0.4825448989868164,2025-05-23 03:41:07
TPDB_YES/svcomp_recHanoi02_true-unreach-call_true-termination_modified.c,ERROR,"[617166] Failed to execute script irankfinder
Traceback (most recent call last):
  File ""irankfinder.py"", line 190, in parse_file
  File ""genericparser/__init__.py"", line 109, in parse
  File ""genericparser/Parser_c.py"", line 21, in parse
Exception: b'Cannot use ""-eager-inline"" with a cyclic call hierarchy!\n'

The above exception was the direct cause of the following exception:

Traceback (most recent call last):
  File ""irankfinder.py"", line 374, in <module>
  File ""irankfinder.py"", line 205, in launch
  File ""irankfinder.py"", line 197, in parse_file
Exception
",failed,0.4534022808074951,2025-05-23 03:41:08
TPDB_YES/PastaA6.c,YES,,success,1.4278252124786377,2025-05-23 03:41:09
TPDB_YES/Avg_true.c,ERROR,"[617194] Failed to execute script irankfinder
Traceback (most recent call last):
  File ""irankfinder.py"", line 190, in parse_file
  File ""genericparser/__init__.py"", line 109, in parse
  File ""genericparser/Parser_c.py"", line 21, in parse
Exception: b'Cannot use ""-eager-inline"" with a cyclic call hierarchy!\n'

The above exception was the direct cause of the following exception:

Traceback (most recent call last):
  File ""irankfinder.py"", line 374, in <module>
  File ""irankfinder.py"", line 205, in launch
  File ""irankfinder.py"", line 197, in parse_file
Exception
",failed,0.3409879207611084,2025-05-23 03:41:09
TPDB_YES/Et1.c,MAYBE,,success,1.8987996578216553,2025-05-23 03:41:11
TPDB_YES/desc_ll_search-ptrdiff_existing.c,ERROR,"[617222] Failed to execute script irankfinder
Traceback (most recent call last):
  File ""irankfinder.py"", line 190, in parse_file
  File ""genericparser/__init__.py"", line 109, in parse
  File ""genericparser/Parser_c.py"", line 25, in parse
  File ""genericparser/Parser_koat.py"", line 25, in parse_string
  File ""lark/lark.py"", line 197, in parse
  File ""lark/parser_frontends.py"", line 137, in parse
  File ""lark/parsers/xearley.py"", line 143, in parse
lark.common.ParseError: Unexpected end of input! Expecting a terminal of: ['__LPAR']

The above exception was the direct cause of the following exception:

Traceback (most recent call last):
  File ""irankfinder.py"", line 374, in <module>
  File ""irankfinder.py"", line 205, in launch
  File ""irankfinder.py"", line 197, in parse_file
Exception
",failed,0.4843597412109375,2025-05-23 03:41:12
TPDB_YES/svcomp_strchr_true-termination.c,ERROR,"[617235] Failed to execute script irankfinder
Traceback (most recent call last):
  File ""irankfinder.py"", line 190, in parse_file
  File ""genericparser/__init__.py"", line 109, in parse
  File ""genericparser/Parser_c.py"", line 25, in parse
  File ""genericparser/Parser_koat.py"", line 25, in parse_string
  File ""lark/lark.py"", line 197, in parse
  File ""lark/parser_frontends.py"", line 137, in parse
  File ""lark/parsers/xearley.py"", line 143, in parse
lark.common.ParseError: Unexpected end of input! Expecting a terminal of: ['__LPAR']

The above exception was the direct cause of the following exception:

Traceback (most recent call last):
  File ""irankfinder.py"", line 374, in <module>
  File ""irankfinder.py"", line 205, in launch
  File ""irankfinder.py"", line 197, in parse_file
Exception
",failed,0.4841327667236328,2025-05-23 03:41:12
TPDB_YES/rec_counter3.c,ERROR,"[617248] Failed to execute script irankfinder
Traceback (most recent call last):
  File ""irankfinder.py"", line 190, in parse_file
  File ""genericparser/__init__.py"", line 109, in parse
  File ""genericparser/Parser_c.py"", line 21, in parse
Exception: b'Cannot use ""-eager-inline"" with a cyclic call hierarchy!\n'

The above exception was the direct cause of the following exception:

Traceback (most recent call last):
  File ""irankfinder.py"", line 374, in <module>
  File ""irankfinder.py"", line 205, in launch
  File ""irankfinder.py"", line 197, in parse_file
Exception
",failed,0.4611392021179199,2025-05-23 03:41:13
TPDB_YES/ChenFlurMukhopadhyay-SAS2012-Ex2.18_true-termination.c,MAYBE,,success,1.1481285095214844,2025-05-23 03:41:14
TPDB_YES/svcomp_a.07.c,YES,,success,2.2548131942749023,2025-05-23 03:41:16
TPDB_YES/min_rf_true-termination.c,MAYBE,,success,3.2624049186706543,2025-05-23 03:41:20
TPDB_YES/CookSeeZuleger-TACAS2013-Fig1_true-termination.c,MAYBE,,success,3.094571113586426,2025-05-23 03:41:23
TPDB_YES/svcomp_java_AG313-alloca.c,ERROR,"[617318] Failed to execute script irankfinder
Traceback (most recent call last):
  File ""irankfinder.py"", line 190, in parse_file
  File ""genericparser/__init__.py"", line 109, in parse
  File ""genericparser/Parser_c.py"", line 25, in parse
  File ""genericparser/Parser_koat.py"", line 25, in parse_string
  File ""lark/lark.py"", line 197, in parse
  File ""lark/parser_frontends.py"", line 137, in parse
  File ""lark/parsers/xearley.py"", line 143, in parse
lark.common.ParseError: Unexpected end of input! Expecting a terminal of: ['__LPAR']

The above exception was the direct cause of the following exception:

Traceback (most recent call last):
  File ""irankfinder.py"", line 374, in <module>
  File ""irankfinder.py"", line 205, in launch
  File ""irankfinder.py"", line 197, in parse_file
Exception
",failed,0.4845736026763916,2025-05-23 03:41:23
TPDB_YES/PodelskiRybalchenko-TACAS2011-Fig4_true-termination.c,MAYBE,,success,2.6808879375457764,2025-05-23 03:41:26
TPDB_YES/svcomp_b.01.c,YES,,success,1.6490540504455566,2025-05-23 03:41:27
TPDB_YES/AliasDarteFeautrierGonnord-SAS2010-wcet2_true-termination.c,MAYBE,,success,1.6803247928619385,2025-05-23 03:41:29
TPDB_YES/ChenFlurMukhopadhyay-SAS2012-Ex2.19_true-termination.c,MAYBE,,success,1.603499174118042,2025-05-23 03:41:31
TPDB_YES/svcomp_twisted.c,MAYBE,,success,5.005754709243774,2025-05-23 03:41:36
TPDB_YES/Bangalore_v4_true-termination.c,YES,,success,1.0292167663574219,2025-05-23 03:41:37
TPDB_YES/PodelskiRybalchenko-VMCAI2004-Ex2_true-termination.c,MAYBE,,success,1.267458200454712,2025-05-23 03:41:38
TPDB_YES/ChenFlurMukhopadhyay-SAS2012-Ex3.04_true-termination.c,MAYBE,,success,1.5244464874267578,2025-05-23 03:41:40
TPDB_YES/PodelskiRybalchenko-VMCAI2004-Ex1_true-termination.c,YES,,success,3.7262420654296875,2025-05-23 03:41:43
TPDB_YES/svcomp_b.02.c,YES,,success,1.7652323246002197,2025-05-23 03:41:45
TPDB_YES/svcomp_openbsd_cstpncpy_alloca.c,ERROR,"[617471] Failed to execute script irankfinder
Traceback (most recent call last):
  File ""irankfinder.py"", line 190, in parse_file
  File ""genericparser/__init__.py"", line 109, in parse
  File ""genericparser/Parser_c.py"", line 25, in parse
  File ""genericparser/Parser_koat.py"", line 25, in parse_string
  File ""lark/lark.py"", line 197, in parse
  File ""lark/parser_frontends.py"", line 137, in parse
  File ""lark/parsers/xearley.py"", line 143, in parse
lark.common.ParseError: Unexpected end of input! Expecting a terminal of: ['__LPAR']

The above exception was the direct cause of the following exception:

Traceback (most recent call last):
  File ""irankfinder.py"", line 374, in <module>
  File ""irankfinder.py"", line 205, in launch
  File ""irankfinder.py"", line 197, in parse_file
Exception
",failed,0.34774112701416016,2025-05-23 03:41:46
TPDB_YES/AliasDarteFeautrierGonnord-SAS2010-complex_true-termination.c,MAYBE,,success,3.381869316101074,2025-05-23 03:41:49
TPDB_YES/AliasDarteFeautrierGonnord-SAS2010-loops_true-termination.c,MAYBE,,success,1.7967219352722168,2025-05-23 03:41:51
TPDB_YES/KroeningSharyginaTsitovichWintersteiger-CAV2010-Ex_true-termination.c,YES,,success,1.5697846412658691,2025-05-23 03:41:52
TPDB_YES/kbfiltr_simpl1_true-unreach-call_true-termination.cil.c,YES,,success,0.49121546745300293,2025-05-23 03:41:53
TPDB_YES/Singapore_true-termination.c,MAYBE,,success,1.833949089050293,2025-05-23 03:41:55
TPDB_YES/CookSeeZuleger-TACAS2013-Fig8a_true-termination.c,MAYBE,,success,1.6232249736785889,2025-05-23 03:41:56
TPDB_YES/ChawdharyCookGulwaniSagivYang-ESOP2008-random1d_true-termination.c,YES,,success,2.8255841732025146,2025-05-23 03:41:59
TPDB_YES/ChenFlurMukhopadhyay-SAS2012-Ex2.01_true-termination.c,MAYBE,,success,1.4778544902801514,2025-05-23 03:42:01
TPDB_YES/PastaB1.c,YES,,success,1.3901290893554688,2025-05-23 03:42:02
TPDB_YES/svcomp_CookSeeZuleger-2013TACAS-Fig7a_true-alloca.c,ERROR,"[617624] Failed to execute script irankfinder
Traceback (most recent call last):
  File ""irankfinder.py"", line 190, in parse_file
  File ""genericparser/__init__.py"", line 109, in parse
  File ""genericparser/Parser_c.py"", line 25, in parse
  File ""genericparser/Parser_koat.py"", line 25, in parse_string
  File ""lark/lark.py"", line 197, in parse
  File ""lark/parser_frontends.py"", line 137, in parse
  File ""lark/parsers/xearley.py"", line 143, in parse
lark.common.ParseError: Unexpected end of input! Expecting a terminal of: ['__LPAR']

The above exception was the direct cause of the following exception:

Traceback (most recent call last):
  File ""irankfinder.py"", line 374, in <module>
  File ""irankfinder.py"", line 205, in launch
  File ""irankfinder.py"", line 197, in parse_file
Exception
",failed,0.3540780544281006,2025-05-23 03:42:02
TPDB_YES/svcomp_BrockschmidtCookFuhs-2013CAV-Fig1_true-alloca.c,ERROR,"[617637] Failed to execute script irankfinder
Traceback (most recent call last):
  File ""irankfinder.py"", line 190, in parse_file
  File ""genericparser/__init__.py"", line 109, in parse
  File ""genericparser/Parser_c.py"", line 25, in parse
  File ""genericparser/Parser_koat.py"", line 25, in parse_string
  File ""lark/lark.py"", line 197, in parse
  File ""lark/parser_frontends.py"", line 137, in parse
  File ""lark/parsers/xearley.py"", line 143, in parse
lark.common.ParseError: Unexpected end of input! Expecting a terminal of: ['__LPAR']

The above exception was the direct cause of the following exception:

Traceback (most recent call last):
  File ""irankfinder.py"", line 374, in <module>
  File ""irankfinder.py"", line 205, in launch
  File ""irankfinder.py"", line 197, in parse_file
Exception
",failed,0.35622334480285645,2025-05-23 03:42:03
TPDB_YES/svcomp_a.09_assume.c,YES,,success,1.9905290603637695,2025-05-23 03:42:05
TPDB_YES/svcomp_subseq_alloca.c,ERROR,"[617664] Failed to execute script irankfinder
Traceback (most recent call last):
  File ""irankfinder.py"", line 190, in parse_file
  File ""genericparser/__init__.py"", line 109, in parse
  File ""genericparser/Parser_c.py"", line 25, in parse
  File ""genericparser/Parser_koat.py"", line 25, in parse_string
  File ""lark/lark.py"", line 197, in parse
  File ""lark/parser_frontends.py"", line 137, in parse
  File ""lark/parsers/xearley.py"", line 143, in parse
lark.common.ParseError: Unexpected end of input! Expecting a terminal of: ['__LPAR']

The above exception was the direct cause of the following exception:

Traceback (most recent call last):
  File ""irankfinder.py"", line 374, in <module>
  File ""irankfinder.py"", line 205, in launch
  File ""irankfinder.py"", line 197, in parse_file
Exception
",failed,0.3562474250793457,2025-05-23 03:42:05
TPDB_YES/svcomp_b.16-alloca.c,ERROR,"[617677] Failed to execute script irankfinder
Traceback (most recent call last):
  File ""irankfinder.py"", line 190, in parse_file
  File ""genericparser/__init__.py"", line 109, in parse
  File ""genericparser/Parser_c.py"", line 25, in parse
  File ""genericparser/Parser_koat.py"", line 25, in parse_string
  File ""lark/lark.py"", line 197, in parse
  File ""lark/parser_frontends.py"", line 137, in parse
  File ""lark/parsers/xearley.py"", line 143, in parse
lark.common.ParseError: Unexpected end of input! Expecting a terminal of: ['__LPAR']

The above exception was the direct cause of the following exception:

Traceback (most recent call last):
  File ""irankfinder.py"", line 374, in <module>
  File ""irankfinder.py"", line 205, in launch
  File ""irankfinder.py"", line 197, in parse_file
Exception
",failed,0.4845755100250244,2025-05-23 03:42:06
TPDB_YES/svcomp_b.06-alloca.c,ERROR,"[617690] Failed to execute script irankfinder
Traceback (most recent call last):
  File ""irankfinder.py"", line 190, in parse_file
  File ""genericparser/__init__.py"", line 109, in parse
  File ""genericparser/Parser_c.py"", line 25, in parse
  File ""genericparser/Parser_koat.py"", line 25, in parse_string
  File ""lark/lark.py"", line 197, in parse
  File ""lark/parser_frontends.py"", line 137, in parse
  File ""lark/parsers/xearley.py"", line 143, in parse
lark.common.ParseError: Unexpected end of input! Expecting a terminal of: ['__LPAR']

The above exception was the direct cause of the following exception:

Traceback (most recent call last):
  File ""irankfinder.py"", line 374, in <module>
  File ""irankfinder.py"", line 205, in launch
  File ""irankfinder.py"", line 197, in parse_file
Exception
",failed,0.4811384677886963,2025-05-23 03:42:06
TPDB_YES/HeizmannHoenickeLeikePodelski-ATVA2013-Fig7_true-termination.c,MAYBE,,success,1.9487981796264648,2025-05-23 03:42:08
TPDB_YES/svcomp_genady_true-alloca.c,ERROR,"[617719] Failed to execute script irankfinder
Traceback (most recent call last):
  File ""irankfinder.py"", line 190, in parse_file
  File ""genericparser/__init__.py"", line 109, in parse
  File ""genericparser/Parser_c.py"", line 25, in parse
  File ""genericparser/Parser_koat.py"", line 25, in parse_string
  File ""lark/lark.py"", line 197, in parse
  File ""lark/parser_frontends.py"", line 137, in parse
  File ""lark/parsers/xearley.py"", line 143, in parse
lark.common.ParseError: Unexpected end of input! Expecting a terminal of: ['__LPAR']

The above exception was the direct cause of the following exception:

Traceback (most recent call last):
  File ""irankfinder.py"", line 374, in <module>
  File ""irankfinder.py"", line 205, in launch
  File ""irankfinder.py"", line 197, in parse_file
Exception
",failed,0.48809075355529785,2025-05-23 03:42:09
TPDB_YES/svcomp_KroeningSharyginaTsitovichWintersteiger-2010CAV-Fig1_true-alloca.c,ERROR,"[617732] Failed to execute script irankfinder
Traceback (most recent call last):
  File ""irankfinder.py"", line 190, in parse_file
  File ""genericparser/__init__.py"", line 109, in parse
  File ""genericparser/Parser_c.py"", line 25, in parse
  File ""genericparser/Parser_koat.py"", line 25, in parse_string
  File ""lark/lark.py"", line 197, in parse
  File ""lark/parser_frontends.py"", line 137, in parse
  File ""lark/parsers/xearley.py"", line 143, in parse
lark.common.ParseError: Unexpected end of input! Expecting a terminal of: ['__LPAR']

The above exception was the direct cause of the following exception:

Traceback (most recent call last):
  File ""irankfinder.py"", line 374, in <module>
  File ""irankfinder.py"", line 205, in launch
  File ""irankfinder.py"", line 197, in parse_file
Exception
",failed,0.35187792778015137,2025-05-23 03:42:09
TPDB_YES/PastaA8.c,YES,,success,1.1548678874969482,2025-05-23 03:42:10
TPDB_YES/LeikeHeizmann-TACAS2014-Fig1_true-termination.c,MAYBE,,success,1.560044288635254,2025-05-23 03:42:12
TPDB_YES/PastaC1.c,MAYBE,,success,1.8833215236663818,2025-05-23 03:42:14
TPDB_YES/fibo_5_false-unreach-call.c,ERROR,"[617787] Failed to execute script irankfinder
Traceback (most recent call last):
  File ""irankfinder.py"", line 190, in parse_file
  File ""genericparser/__init__.py"", line 109, in parse
  File ""genericparser/Parser_c.py"", line 21, in parse
Exception: b'Cannot use ""-eager-inline"" with a cyclic call hierarchy!\n'

The above exception was the direct cause of the following exception:

Traceback (most recent call last):
  File ""irankfinder.py"", line 374, in <module>
  File ""irankfinder.py"", line 205, in launch
  File ""irankfinder.py"", line 197, in parse_file
Exception
",failed,0.45547914505004883,2025-05-23 03:42:14
TPDB_YES/Urban-WST2013-Fig2_true-termination.c,MAYBE,,success,1.5106322765350342,2025-05-23 03:42:16
TPDB_YES/svcomp_NoriSharma-2013FSE-Fig7_true-alloca.c,ERROR,"[617815] Failed to execute script irankfinder
Traceback (most recent call last):
  File ""irankfinder.py"", line 190, in parse_file
  File ""genericparser/__init__.py"", line 109, in parse
  File ""genericparser/Parser_c.py"", line 25, in parse
  File ""genericparser/Parser_koat.py"", line 25, in parse_string
  File ""lark/lark.py"", line 197, in parse
  File ""lark/parser_frontends.py"", line 137, in parse
  File ""lark/parsers/xearley.py"", line 143, in parse
lark.common.ParseError: Unexpected end of input! Expecting a terminal of: ['__LPAR']

The above exception was the direct cause of the following exception:

Traceback (most recent call last):
  File ""irankfinder.py"", line 374, in <module>
  File ""irankfinder.py"", line 205, in launch
  File ""irankfinder.py"", line 197, in parse_file
Exception
",failed,0.47877001762390137,2025-05-23 03:42:16
TPDB_YES/PastaA1.c,MAYBE,,success,1.8976407051086426,2025-05-23 03:42:18
TPDB_YES/svcomp_array02_alloca.c,ERROR,"[617842] Failed to execute script irankfinder
Traceback (most recent call last):
  File ""irankfinder.py"", line 190, in parse_file
  File ""genericparser/__init__.py"", line 109, in parse
  File ""genericparser/Parser_c.py"", line 25, in parse
  File ""genericparser/Parser_koat.py"", line 25, in parse_string
  File ""lark/lark.py"", line 197, in parse
  File ""lark/parser_frontends.py"", line 137, in parse
  File ""lark/parsers/xearley.py"", line 143, in parse
lark.common.ParseError: Unexpected end of input! Expecting a terminal of: ['__LPAR']

The above exception was the direct cause of the following exception:

Traceback (most recent call last):
  File ""irankfinder.py"", line 374, in <module>
  File ""irankfinder.py"", line 205, in launch
  File ""irankfinder.py"", line 197, in parse_file
Exception
",failed,0.48581480979919434,2025-05-23 03:42:18
TPDB_YES/easy1_true-termination.c,MAYBE,,success,1.6238136291503906,2025-05-23 03:42:20
TPDB_YES/AliasDarteFeautrierGonnord-SAS2010-random2d_true-termination.c,MAYBE,,success,6.511678218841553,2025-05-23 03:42:27
TPDB_YES/Nested.c,MAYBE,,success,1.2553400993347168,2025-05-23 03:42:28
TPDB_YES/svcomp_a.04-alloca.c,ERROR,"[617908] Failed to execute script irankfinder
Traceback (most recent call last):
  File ""irankfinder.py"", line 190, in parse_file
  File ""genericparser/__init__.py"", line 109, in parse
  File ""genericparser/Parser_c.py"", line 25, in parse
  File ""genericparser/Parser_koat.py"", line 25, in parse_string
  File ""lark/lark.py"", line 197, in parse
  File ""lark/parser_frontends.py"", line 137, in parse
  File ""lark/parsers/xearley.py"", line 143, in parse
lark.common.ParseError: Unexpected end of input! Expecting a terminal of: ['__LPAR']

The above exception was the direct cause of the following exception:

Traceback (most recent call last):
  File ""irankfinder.py"", line 374, in <module>
  File ""irankfinder.py"", line 205, in launch
  File ""irankfinder.py"", line 197, in parse_file
Exception
",failed,0.47902727127075195,2025-05-23 03:42:28
TPDB_YES/svcomp_java_Continue1-alloca.c,ERROR,"[617921] Failed to execute script irankfinder
Traceback (most recent call last):
  File ""irankfinder.py"", line 190, in parse_file
  File ""genericparser/__init__.py"", line 109, in parse
  File ""genericparser/Parser_c.py"", line 25, in parse
  File ""genericparser/Parser_koat.py"", line 25, in parse_string
  File ""lark/lark.py"", line 197, in parse
  File ""lark/parser_frontends.py"", line 137, in parse
  File ""lark/parsers/xearley.py"", line 143, in parse
lark.common.ParseError: Unexpected end of input! Expecting a terminal of: ['__LPAR']

The above exception was the direct cause of the following exception:

Traceback (most recent call last):
  File ""irankfinder.py"", line 374, in <module>
  File ""irankfinder.py"", line 205, in launch
  File ""irankfinder.py"", line 197, in parse_file
Exception
",failed,0.4737823009490967,2025-05-23 03:42:29
TPDB_YES/McCarthy91_false-unreach-call_false-termination.c,ERROR,"[617934] Failed to execute script irankfinder
Traceback (most recent call last):
  File ""irankfinder.py"", line 190, in parse_file
  File ""genericparser/__init__.py"", line 109, in parse
  File ""genericparser/Parser_c.py"", line 21, in parse
Exception: b'Cannot use ""-eager-inline"" with a cyclic call hierarchy!\n'

The above exception was the direct cause of the following exception:

Traceback (most recent call last):
  File ""irankfinder.py"", line 374, in <module>
  File ""irankfinder.py"", line 205, in launch
  File ""irankfinder.py"", line 197, in parse_file
Exception
",failed,0.4499375820159912,2025-05-23 03:42:29
TPDB_YES/svcomp_b.18.c,MAYBE,,success,3.4020113945007324,2025-05-23 03:42:33
TPDB_YES/svcomp_java_LogBuiltIn.c,YES,,success,1.1849656105041504,2025-05-23 03:42:34
TPDB_YES/svcomp_c.08-alloca.c,ERROR,"[617977] Failed to execute script irankfinder
Traceback (most recent call last):
  File ""irankfinder.py"", line 190, in parse_file
  File ""genericparser/__init__.py"", line 109, in parse
  File ""genericparser/Parser_c.py"", line 25, in parse
  File ""genericparser/Parser_koat.py"", line 25, in parse_string
  File ""lark/lark.py"", line 197, in parse
  File ""lark/parser_frontends.py"", line 137, in parse
  File ""lark/parsers/xearley.py"", line 143, in parse
lark.common.ParseError: Unexpected end of input! Expecting a terminal of: ['__LPAR']

The above exception was the direct cause of the following exception:

Traceback (most recent call last):
  File ""irankfinder.py"", line 374, in <module>
  File ""irankfinder.py"", line 205, in launch
  File ""irankfinder.py"", line 197, in parse_file
Exception
",failed,0.4774188995361328,2025-05-23 03:42:34
TPDB_YES/email_spec0_product05_true-unreach-call.cil.c,ERROR,Execution timed out,failed,120,2025-05-23 03:44:35
TPDB_YES/svcomp_NoriSharma-2013FSE-Fig8_true-alloca.c,ERROR,"[618005] Failed to execute script irankfinder
Traceback (most recent call last):
  File ""irankfinder.py"", line 190, in parse_file
  File ""genericparser/__init__.py"", line 109, in parse
  File ""genericparser/Parser_c.py"", line 25, in parse
  File ""genericparser/Parser_koat.py"", line 25, in parse_string
  File ""lark/lark.py"", line 197, in parse
  File ""lark/parser_frontends.py"", line 137, in parse
  File ""lark/parsers/xearley.py"", line 143, in parse
lark.common.ParseError: Unexpected end of input! Expecting a terminal of: ['__LPAR']

The above exception was the direct cause of the following exception:

Traceback (most recent call last):
  File ""irankfinder.py"", line 374, in <module>
  File ""irankfinder.py"", line 205, in launch
  File ""irankfinder.py"", line 197, in parse_file
Exception
",failed,0.4794628620147705,2025-05-23 03:44:35
TPDB_YES/svcomp_b.18-alloca.c,ERROR,"[618018] Failed to execute script irankfinder
Traceback (most recent call last):
  File ""irankfinder.py"", line 190, in parse_file
  File ""genericparser/__init__.py"", line 109, in parse
  File ""genericparser/Parser_c.py"", line 25, in parse
  File ""genericparser/Parser_koat.py"", line 25, in parse_string
  File ""lark/lark.py"", line 197, in parse
  File ""lark/parser_frontends.py"", line 137, in parse
  File ""lark/parsers/xearley.py"", line 143, in parse
lark.common.ParseError: Unexpected end of input! Expecting a terminal of: ['__LPAR']

The above exception was the direct cause of the following exception:

Traceback (most recent call last):
  File ""irankfinder.py"", line 374, in <module>
  File ""irankfinder.py"", line 205, in launch
  File ""irankfinder.py"", line 197, in parse_file
Exception
",failed,0.48253417015075684,2025-05-23 03:44:36
TPDB_YES/CookSeeZuleger-TACAS2013-Fig7b_true-termination.c,MAYBE,,success,6.490934371948242,2025-05-23 03:44:42
TPDB_YES/svcomp_b.13-alloca.c,ERROR,"[618045] Failed to execute script irankfinder
Traceback (most recent call last):
  File ""irankfinder.py"", line 190, in parse_file
  File ""genericparser/__init__.py"", line 109, in parse
  File ""genericparser/Parser_c.py"", line 25, in parse
  File ""genericparser/Parser_koat.py"", line 25, in parse_string
  File ""lark/lark.py"", line 197, in parse
  File ""lark/parser_frontends.py"", line 137, in parse
  File ""lark/parsers/xearley.py"", line 143, in parse
lark.common.ParseError: Unexpected end of input! Expecting a terminal of: ['__LPAR']

The above exception was the direct cause of the following exception:

Traceback (most recent call last):
  File ""irankfinder.py"", line 374, in <module>
  File ""irankfinder.py"", line 205, in launch
  File ""irankfinder.py"", line 197, in parse_file
Exception
",failed,0.48665547370910645,2025-05-23 03:44:43
TPDB_YES/svcomp_cstrchr_true_alloca.c,ERROR,"[618058] Failed to execute script irankfinder
Traceback (most recent call last):
  File ""irankfinder.py"", line 190, in parse_file
  File ""genericparser/__init__.py"", line 109, in parse
  File ""genericparser/Parser_c.py"", line 25, in parse
  File ""genericparser/Parser_koat.py"", line 25, in parse_string
  File ""lark/lark.py"", line 197, in parse
  File ""lark/parser_frontends.py"", line 137, in parse
  File ""lark/parsers/xearley.py"", line 143, in parse
lark.common.ParseError: Unexpected end of input! Expecting a terminal of: ['__LPAR']

The above exception was the direct cause of the following exception:

Traceback (most recent call last):
  File ""irankfinder.py"", line 374, in <module>
  File ""irankfinder.py"", line 205, in launch
  File ""irankfinder.py"", line 197, in parse_file
Exception
",failed,0.48068714141845703,2025-05-23 03:44:43
TPDB_YES/HeizmannHoenickeLeikePodelski-ATVA2013-Fig1_true-termination.c,MAYBE,,success,1.252096176147461,2025-05-23 03:44:44
TPDB_YES/svcomp_cstrncmp_true_alloca.c,ERROR,"[618085] Failed to execute script irankfinder
Traceback (most recent call last):
  File ""irankfinder.py"", line 190, in parse_file
  File ""genericparser/__init__.py"", line 109, in parse
  File ""genericparser/Parser_c.py"", line 25, in parse
  File ""genericparser/Parser_koat.py"", line 25, in parse_string
  File ""lark/lark.py"", line 197, in parse
  File ""lark/parser_frontends.py"", line 137, in parse
  File ""lark/parsers/xearley.py"", line 143, in parse
lark.common.ParseError: Unexpected end of input! Expecting a terminal of: ['__LPAR']

The above exception was the direct cause of the following exception:

Traceback (most recent call last):
  File ""irankfinder.py"", line 374, in <module>
  File ""irankfinder.py"", line 205, in launch
  File ""irankfinder.py"", line 197, in parse_file
Exception
",failed,0.4789164066314697,2025-05-23 03:44:45
TPDB_YES/standard_compare_true-unreach-call_ground.c,MAYBE,,success,4.396264314651489,2025-05-23 03:44:49
TPDB_YES/svcomp_b.05-alloca.c,ERROR,"[618112] Failed to execute script irankfinder
Traceback (most recent call last):
  File ""irankfinder.py"", line 190, in parse_file
  File ""genericparser/__init__.py"", line 109, in parse
  File ""genericparser/Parser_c.py"", line 25, in parse
  File ""genericparser/Parser_koat.py"", line 25, in parse_string
  File ""lark/lark.py"", line 197, in parse
  File ""lark/parser_frontends.py"", line 137, in parse
  File ""lark/parsers/xearley.py"", line 143, in parse
lark.common.ParseError: Unexpected end of input! Expecting a terminal of: ['__LPAR']

The above exception was the direct cause of the following exception:

Traceback (most recent call last):
  File ""irankfinder.py"", line 374, in <module>
  File ""irankfinder.py"", line 205, in launch
  File ""irankfinder.py"", line 197, in parse_file
Exception
",failed,0.35948896408081055,2025-05-23 03:44:50
TPDB_YES/svcomp_cstrcmp_true-termination.c,ERROR,"[618125] Failed to execute script irankfinder
Traceback (most recent call last):
  File ""irankfinder.py"", line 190, in parse_file
  File ""genericparser/__init__.py"", line 109, in parse
  File ""genericparser/Parser_c.py"", line 25, in parse
  File ""genericparser/Parser_koat.py"", line 25, in parse_string
  File ""lark/lark.py"", line 197, in parse
  File ""lark/parser_frontends.py"", line 137, in parse
  File ""lark/parsers/xearley.py"", line 143, in parse
lark.common.ParseError: Unexpected end of input! Expecting a terminal of: ['__LPAR']

The above exception was the direct cause of the following exception:

Traceback (most recent call last):
  File ""irankfinder.py"", line 374, in <module>
  File ""irankfinder.py"", line 205, in launch
  File ""irankfinder.py"", line 197, in parse_file
Exception
",failed,0.46587228775024414,2025-05-23 03:44:50
TPDB_YES/svcomp_cstrpbrk_true_alloca.c,ERROR,"[618138] Failed to execute script irankfinder
Traceback (most recent call last):
  File ""irankfinder.py"", line 190, in parse_file
  File ""genericparser/__init__.py"", line 109, in parse
  File ""genericparser/Parser_c.py"", line 25, in parse
  File ""genericparser/Parser_koat.py"", line 25, in parse_string
  File ""lark/lark.py"", line 197, in parse
  File ""lark/parser_frontends.py"", line 137, in parse
  File ""lark/parsers/xearley.py"", line 143, in parse
lark.common.ParseError: Unexpected end of input! Expecting a terminal of: ['__LPAR']

The above exception was the direct cause of the following exception:

Traceback (most recent call last):
  File ""irankfinder.py"", line 374, in <module>
  File ""irankfinder.py"", line 205, in launch
  File ""irankfinder.py"", line 197, in parse_file
Exception
",failed,0.3519265651702881,2025-05-23 03:44:50
TPDB_YES/Toulouse-MultiBranchesToLoop_true-termination.c,MAYBE,,success,5.873286485671997,2025-05-23 03:44:56
TPDB_YES/Pure3Phase_true-termination.c,MAYBE,,success,3.00862455368042,2025-05-23 03:44:59
TPDB_YES/AliasDarteFeautrierGonnord-SAS2010-speedpldi3_true-termination.c,MAYBE,,success,2.1062746047973633,2025-05-23 03:45:01
TPDB_YES/svcomp_openbsd_cstrlcpy_alloca.c,ERROR,"[618193] Failed to execute script irankfinder
Traceback (most recent call last):
  File ""irankfinder.py"", line 190, in parse_file
  File ""genericparser/__init__.py"", line 109, in parse
  File ""genericparser/Parser_c.py"", line 25, in parse
  File ""genericparser/Parser_koat.py"", line 25, in parse_string
  File ""lark/lark.py"", line 197, in parse
  File ""lark/parser_frontends.py"", line 137, in parse
  File ""lark/parsers/xearley.py"", line 143, in parse
lark.common.ParseError: Unexpected end of input! Expecting a terminal of: ['__LPAR']

The above exception was the direct cause of the following exception:

Traceback (most recent call last):
  File ""irankfinder.py"", line 374, in <module>
  File ""irankfinder.py"", line 205, in launch
  File ""irankfinder.py"", line 197, in parse_file
Exception
",failed,0.35473179817199707,2025-05-23 03:45:02
TPDB_YES/Pure2Phase_true-termination.c,MAYBE,,success,1.9565458297729492,2025-05-23 03:45:04
TPDB_YES/McCarthy91_Recursion_true-termination.c,ERROR,"[618220] Failed to execute script irankfinder
Traceback (most recent call last):
  File ""irankfinder.py"", line 190, in parse_file
  File ""genericparser/__init__.py"", line 109, in parse
  File ""genericparser/Parser_c.py"", line 21, in parse
Exception: b'Cannot use ""-eager-inline"" with a cyclic call hierarchy!\n'

The above exception was the direct cause of the following exception:

Traceback (most recent call last):
  File ""irankfinder.py"", line 374, in <module>
  File ""irankfinder.py"", line 205, in launch
  File ""irankfinder.py"", line 197, in parse_file
Exception
",failed,0.4598550796508789,2025-05-23 03:45:04
TPDB_YES/svcomp_ex2.c,MAYBE,,success,3.514688014984131,2025-05-23 03:45:08
TPDB_YES/ChawdharyCookGulwaniSagivYang-ESOP2008-aaron12_true-termination.c,MAYBE,,success,3.557023763656616,2025-05-23 03:45:11
TPDB_YES/svcomp_cstrcpy_alloca.c,ERROR,"[618262] Failed to execute script irankfinder
Traceback (most recent call last):
  File ""irankfinder.py"", line 190, in parse_file
  File ""genericparser/__init__.py"", line 109, in parse
  File ""genericparser/Parser_c.py"", line 25, in parse
  File ""genericparser/Parser_koat.py"", line 25, in parse_string
  File ""lark/lark.py"", line 197, in parse
  File ""lark/parser_frontends.py"", line 137, in parse
  File ""lark/parsers/xearley.py"", line 143, in parse
lark.common.ParseError: Unexpected end of input! Expecting a terminal of: ['__LPAR']

The above exception was the direct cause of the following exception:

Traceback (most recent call last):
  File ""irankfinder.py"", line 374, in <module>
  File ""irankfinder.py"", line 205, in launch
  File ""irankfinder.py"", line 197, in parse_file
Exception
",failed,0.35672593116760254,2025-05-23 03:45:12
TPDB_YES/PastaB7.c,YES,,success,2.1044628620147705,2025-05-23 03:45:14
TPDB_YES/svcomp_array03_alloca.c,ERROR,"[618289] Failed to execute script irankfinder
Traceback (most recent call last):
  File ""irankfinder.py"", line 190, in parse_file
  File ""genericparser/__init__.py"", line 109, in parse
  File ""genericparser/Parser_c.py"", line 25, in parse
  File ""genericparser/Parser_koat.py"", line 25, in parse_string
  File ""lark/lark.py"", line 197, in parse
  File ""lark/parser_frontends.py"", line 137, in parse
  File ""lark/parsers/xearley.py"", line 143, in parse
lark.common.ParseError: Unexpected end of input! Expecting a terminal of: ['__LPAR']

The above exception was the direct cause of the following exception:

Traceback (most recent call last):
  File ""irankfinder.py"", line 374, in <module>
  File ""irankfinder.py"", line 205, in launch
  File ""irankfinder.py"", line 197, in parse_file
Exception
",failed,0.4847989082336426,2025-05-23 03:45:14
TPDB_YES/svcomp_a.05.c,YES,,success,1.7708218097686768,2025-05-23 03:45:16
TPDB_YES/svcomp_java_LogBuiltIn-alloca.c,ERROR,"[618316] Failed to execute script irankfinder
Traceback (most recent call last):
  File ""irankfinder.py"", line 190, in parse_file
  File ""genericparser/__init__.py"", line 109, in parse
  File ""genericparser/Parser_c.py"", line 25, in parse
  File ""genericparser/Parser_koat.py"", line 25, in parse_string
  File ""lark/lark.py"", line 197, in parse
  File ""lark/parser_frontends.py"", line 137, in parse
  File ""lark/parsers/xearley.py"", line 143, in parse
lark.common.ParseError: Unexpected end of input! Expecting a terminal of: ['__LPAR']

The above exception was the direct cause of the following exception:

Traceback (most recent call last):
  File ""irankfinder.py"", line 374, in <module>
  File ""irankfinder.py"", line 205, in launch
  File ""irankfinder.py"", line 197, in parse_file
Exception
",failed,0.34900903701782227,2025-05-23 03:45:16
TPDB_YES/desc_ll_search_mod.c,ERROR,"[618329] Failed to execute script irankfinder
Traceback (most recent call last):
  File ""irankfinder.py"", line 190, in parse_file
  File ""genericparser/__init__.py"", line 109, in parse
  File ""genericparser/Parser_c.py"", line 25, in parse
  File ""genericparser/Parser_koat.py"", line 25, in parse_string
  File ""lark/lark.py"", line 197, in parse
  File ""lark/parser_frontends.py"", line 137, in parse
  File ""lark/parsers/xearley.py"", line 143, in parse
lark.common.ParseError: Unexpected end of input! Expecting a terminal of: ['__LPAR']

The above exception was the direct cause of the following exception:

Traceback (most recent call last):
  File ""irankfinder.py"", line 374, in <module>
  File ""irankfinder.py"", line 205, in launch
  File ""irankfinder.py"", line 197, in parse_file
Exception
",failed,0.3541271686553955,2025-05-23 03:45:17
TPDB_YES/svcomp_b.10.c,YES,,success,3.4473178386688232,2025-05-23 03:45:20
TPDB_YES/svcomp_Toulouse-MultiBranchesToLoop_true-alloca.c,ERROR,"[618356] Failed to execute script irankfinder
Traceback (most recent call last):
  File ""irankfinder.py"", line 190, in parse_file
  File ""genericparser/__init__.py"", line 109, in parse
  File ""genericparser/Parser_c.py"", line 25, in parse
  File ""genericparser/Parser_koat.py"", line 25, in parse_string
  File ""lark/lark.py"", line 197, in parse
  File ""lark/parser_frontends.py"", line 137, in parse
  File ""lark/parsers/xearley.py"", line 143, in parse
lark.common.ParseError: Unexpected end of input! Expecting a terminal of: ['__LPAR']

The above exception was the direct cause of the following exception:

Traceback (most recent call last):
  File ""irankfinder.py"", line 374, in <module>
  File ""irankfinder.py"", line 205, in launch
  File ""irankfinder.py"", line 197, in parse_file
Exception
",failed,0.38369297981262207,2025-05-23 03:45:21
TPDB_YES/AliasDarteFeautrierGonnord-SAS2010-while2_true-termination.c,MAYBE,,success,1.9208173751831055,2025-05-23 03:45:23
TPDB_YES/AliasDarteFeautrierGonnord-SAS2010-Fig1_true-termination.c,MAYBE,,success,5.6242711544036865,2025-05-23 03:45:28
TPDB_YES/ChenFlurMukhopadhyay-SAS2012-Ex2.20_true-termination.c,YES,,success,1.9531614780426025,2025-05-23 03:45:30
TPDB_YES/svcomp_b.11.c,YES,,success,3.925732374191284,2025-05-23 03:45:34
TPDB_YES/desc_ll_with_offset_search.c,ERROR,"[618425] Failed to execute script irankfinder
Traceback (most recent call last):
  File ""irankfinder.py"", line 190, in parse_file
  File ""genericparser/__init__.py"", line 109, in parse
  File ""genericparser/Parser_c.py"", line 25, in parse
  File ""genericparser/Parser_koat.py"", line 25, in parse_string
  File ""lark/lark.py"", line 197, in parse
  File ""lark/parser_frontends.py"", line 137, in parse
  File ""lark/parsers/xearley.py"", line 143, in parse
lark.common.ParseError: Unexpected end of input! Expecting a terminal of: ['__LPAR']

The above exception was the direct cause of the following exception:

Traceback (most recent call last):
  File ""irankfinder.py"", line 374, in <module>
  File ""irankfinder.py"", line 205, in launch
  File ""irankfinder.py"", line 197, in parse_file
Exception
",failed,0.3523688316345215,2025-05-23 03:45:34
TPDB_YES/svcomp_ex1-alloca.c,ERROR,"[618438] Failed to execute script irankfinder
Traceback (most recent call last):
  File ""irankfinder.py"", line 190, in parse_file
  File ""genericparser/__init__.py"", line 109, in parse
  File ""genericparser/Parser_c.py"", line 25, in parse
  File ""genericparser/Parser_koat.py"", line 25, in parse_string
  File ""lark/lark.py"", line 197, in parse
  File ""lark/parser_frontends.py"", line 137, in parse
  File ""lark/parsers/xearley.py"", line 143, in parse
lark.common.ParseError: Unexpected end of input! Expecting a terminal of: ['__LPAR']

The above exception was the direct cause of the following exception:

Traceback (most recent call last):
  File ""irankfinder.py"", line 374, in <module>
  File ""irankfinder.py"", line 205, in launch
  File ""irankfinder.py"", line 197, in parse_file
Exception
",failed,0.48413705825805664,2025-05-23 03:45:35
TPDB_YES/Ackermann_true-termination.c,ERROR,"[618451] Failed to execute script irankfinder
Traceback (most recent call last):
  File ""irankfinder.py"", line 190, in parse_file
  File ""genericparser/__init__.py"", line 109, in parse
  File ""genericparser/Parser_c.py"", line 21, in parse
Exception: b'Cannot use ""-eager-inline"" with a cyclic call hierarchy!\n'

The above exception was the direct cause of the following exception:

Traceback (most recent call last):
  File ""irankfinder.py"", line 374, in <module>
  File ""irankfinder.py"", line 205, in launch
  File ""irankfinder.py"", line 197, in parse_file
Exception
",failed,0.32958555221557617,2025-05-23 03:45:35
TPDB_YES/HeizmannHoenickeLeikePodelski-ATVA2013-Fig4_true-termination.c,YES,,success,1.2390332221984863,2025-05-23 03:45:37
TPDB_YES/Lobnya-Boolean-Reordered_true-termination.c,MAYBE,,success,1.6635537147521973,2025-05-23 03:45:38
TPDB_YES/AliasDarteFeautrierGonnord-SAS2010-Fig2b_true-termination.c,MAYBE,,success,14.511325359344482,2025-05-23 03:45:53
TPDB_YES/svcomp_GulwaniJainKoskinen-2009PLDI-Fig1_true-alloca.c,ERROR,"[618507] Failed to execute script irankfinder
Traceback (most recent call last):
  File ""irankfinder.py"", line 190, in parse_file
  File ""genericparser/__init__.py"", line 109, in parse
  File ""genericparser/Parser_c.py"", line 25, in parse
  File ""genericparser/Parser_koat.py"", line 25, in parse_string
  File ""lark/lark.py"", line 197, in parse
  File ""lark/parser_frontends.py"", line 137, in parse
  File ""lark/parsers/xearley.py"", line 143, in parse
lark.common.ParseError: Unexpected end of input! Expecting a terminal of: ['__LPAR']

The above exception was the direct cause of the following exception:

Traceback (most recent call last):
  File ""irankfinder.py"", line 374, in <module>
  File ""irankfinder.py"", line 205, in launch
  File ""irankfinder.py"", line 197, in parse_file
Exception
",failed,0.47968387603759766,2025-05-23 03:45:53
TPDB_YES/NestedRecursion_1b_true-termination.c,ERROR,"[618520] Failed to execute script irankfinder
Traceback (most recent call last):
  File ""irankfinder.py"", line 190, in parse_file
  File ""genericparser/__init__.py"", line 109, in parse
  File ""genericparser/Parser_c.py"", line 21, in parse
Exception: b'Cannot use ""-eager-inline"" with a cyclic call hierarchy!\n'

The above exception was the direct cause of the following exception:

Traceback (most recent call last):
  File ""irankfinder.py"", line 374, in <module>
  File ""irankfinder.py"", line 205, in launch
  File ""irankfinder.py"", line 197, in parse_file
Exception
",failed,0.33779311180114746,2025-05-23 03:45:54
TPDB_YES/svcomp_cstrncmp_true-termination.c,ERROR,"[618534] Failed to execute script irankfinder
Traceback (most recent call last):
  File ""irankfinder.py"", line 190, in parse_file
  File ""genericparser/__init__.py"", line 109, in parse
  File ""genericparser/Parser_c.py"", line 25, in parse
  File ""genericparser/Parser_koat.py"", line 25, in parse_string
  File ""lark/lark.py"", line 197, in parse
  File ""lark/parser_frontends.py"", line 137, in parse
  File ""lark/parsers/xearley.py"", line 143, in parse
lark.common.ParseError: Unexpected end of input! Expecting a terminal of: ['__LPAR']

The above exception was the direct cause of the following exception:

Traceback (most recent call last):
  File ""irankfinder.py"", line 374, in <module>
  File ""irankfinder.py"", line 205, in launch
  File ""irankfinder.py"", line 197, in parse_file
Exception
",failed,0.4754364490509033,2025-05-23 03:45:54
TPDB_YES/svcomp_ex3b-alloca.c,ERROR,"[618547] Failed to execute script irankfinder
Traceback (most recent call last):
  File ""irankfinder.py"", line 190, in parse_file
  File ""genericparser/__init__.py"", line 109, in parse
  File ""genericparser/Parser_c.py"", line 25, in parse
  File ""genericparser/Parser_koat.py"", line 25, in parse_string
  File ""lark/lark.py"", line 197, in parse
  File ""lark/parser_frontends.py"", line 137, in parse
  File ""lark/parsers/xearley.py"", line 143, in parse
lark.common.ParseError: Unexpected end of input! Expecting a terminal of: ['__LPAR']

The above exception was the direct cause of the following exception:

Traceback (most recent call last):
  File ""irankfinder.py"", line 374, in <module>
  File ""irankfinder.py"", line 205, in launch
  File ""irankfinder.py"", line 197, in parse_file
Exception
",failed,0.34912633895874023,2025-05-23 03:45:54
TPDB_YES/svcomp_java_Sequence-alloca.c,ERROR,"[618560] Failed to execute script irankfinder
Traceback (most recent call last):
  File ""irankfinder.py"", line 190, in parse_file
  File ""genericparser/__init__.py"", line 109, in parse
  File ""genericparser/Parser_c.py"", line 25, in parse
  File ""genericparser/Parser_koat.py"", line 25, in parse_string
  File ""lark/lark.py"", line 197, in parse
  File ""lark/parser_frontends.py"", line 137, in parse
  File ""lark/parsers/xearley.py"", line 143, in parse
lark.common.ParseError: Unexpected end of input! Expecting a terminal of: ['__LPAR']

The above exception was the direct cause of the following exception:

Traceback (most recent call last):
  File ""irankfinder.py"", line 374, in <module>
  File ""irankfinder.py"", line 205, in launch
  File ""irankfinder.py"", line 197, in parse_file
Exception
",failed,0.35336995124816895,2025-05-23 03:45:55
TPDB_YES/ChenFlurMukhopadhyay-SAS2012-Ex1.01_true-termination.c,MAYBE,,success,1.2671847343444824,2025-05-23 03:45:56
TPDB_YES/ChenFlurMukhopadhyay-SAS2012-Ex3.07_true-termination.c,MAYBE,,success,1.9778246879577637,2025-05-23 03:45:58
TPDB_YES/svcomp_openbsd_cstrcpy_alloca.c,ERROR,"[618601] Failed to execute script irankfinder
Traceback (most recent call last):
  File ""irankfinder.py"", line 190, in parse_file
  File ""genericparser/__init__.py"", line 109, in parse
  File ""genericparser/Parser_c.py"", line 25, in parse
  File ""genericparser/Parser_koat.py"", line 25, in parse_string
  File ""lark/lark.py"", line 197, in parse
  File ""lark/parser_frontends.py"", line 137, in parse
  File ""lark/parsers/xearley.py"", line 143, in parse
lark.common.ParseError: Unexpected end of input! Expecting a terminal of: ['__LPAR']

The above exception was the direct cause of the following exception:

Traceback (most recent call last):
  File ""irankfinder.py"", line 374, in <module>
  File ""irankfinder.py"", line 205, in launch
  File ""irankfinder.py"", line 197, in parse_file
Exception
",failed,0.4860837459564209,2025-05-23 03:45:59
TPDB_YES/svcomp_substring_alloca.c,ERROR,"[618614] Failed to execute script irankfinder
Traceback (most recent call last):
  File ""irankfinder.py"", line 190, in parse_file
  File ""genericparser/__init__.py"", line 109, in parse
  File ""genericparser/Parser_c.py"", line 25, in parse
  File ""genericparser/Parser_koat.py"", line 25, in parse_string
  File ""lark/lark.py"", line 197, in parse
  File ""lark/parser_frontends.py"", line 137, in parse
  File ""lark/parsers/xearley.py"", line 143, in parse
lark.common.ParseError: Unexpected end of input! Expecting a terminal of: ['__LPAR']

The above exception was the direct cause of the following exception:

Traceback (most recent call last):
  File ""irankfinder.py"", line 374, in <module>
  File ""irankfinder.py"", line 205, in launch
  File ""irankfinder.py"", line 197, in parse_file
Exception
",failed,0.482774019241333,2025-05-23 03:45:59
TPDB_YES/GulavaniGulwani-CAV2008-Fig1a_true-termination.c,MAYBE,,success,2.2138311862945557,2025-05-23 03:46:01
TPDB_YES/ChenFlurMukhopadhyay-SAS2012-Fig1_true-termination.c,MAYBE,,success,1.4013738632202148,2025-05-23 03:46:03
TPDB_YES/svcomp_a.08-alloca.c,ERROR,"[618655] Failed to execute script irankfinder
Traceback (most recent call last):
  File ""irankfinder.py"", line 190, in parse_file
  File ""genericparser/__init__.py"", line 109, in parse
  File ""genericparser/Parser_c.py"", line 25, in parse
  File ""genericparser/Parser_koat.py"", line 25, in parse_string
  File ""lark/lark.py"", line 197, in parse
  File ""lark/parser_frontends.py"", line 137, in parse
  File ""lark/parsers/xearley.py"", line 143, in parse
lark.common.ParseError: Unexpected end of input! Expecting a terminal of: ['__LPAR']

The above exception was the direct cause of the following exception:

Traceback (most recent call last):
  File ""irankfinder.py"", line 374, in <module>
  File ""irankfinder.py"", line 205, in launch
  File ""irankfinder.py"", line 197, in parse_file
Exception
",failed,0.3550903797149658,2025-05-23 03:46:03
TPDB_YES/Et1_true.c,ERROR,"[618668] Failed to execute script irankfinder
Traceback (most recent call last):
  File ""irankfinder.py"", line 190, in parse_file
  File ""genericparser/__init__.py"", line 109, in parse
  File ""genericparser/Parser_c.py"", line 21, in parse
Exception: b'Cannot use ""-eager-inline"" with a cyclic call hierarchy!\n'

The above exception was the direct cause of the following exception:

Traceback (most recent call last):
  File ""irankfinder.py"", line 374, in <module>
  File ""irankfinder.py"", line 205, in launch
  File ""irankfinder.py"", line 197, in parse_file
Exception
",failed,0.33605265617370605,2025-05-23 03:46:03
TPDB_YES/Waldkirch_true-termination.c,YES,,success,0.9467577934265137,2025-05-23 03:46:04
TPDB_YES/AliasDarteFeautrierGonnord-SAS2010-speedpldi2_true-termination.c,YES,,success,1.6271586418151855,2025-05-23 03:46:06
TPDB_YES/TerminatorRec02_true.c,ERROR,"[618710] Failed to execute script irankfinder
Traceback (most recent call last):
  File ""irankfinder.py"", line 190, in parse_file
  File ""genericparser/__init__.py"", line 109, in parse
  File ""genericparser/Parser_c.py"", line 21, in parse
Exception: b'Cannot use ""-eager-inline"" with a cyclic call hierarchy!\n'

The above exception was the direct cause of the following exception:

Traceback (most recent call last):
  File ""irankfinder.py"", line 374, in <module>
  File ""irankfinder.py"", line 205, in launch
  File ""irankfinder.py"", line 197, in parse_file
Exception
",failed,0.33605384826660156,2025-05-23 03:46:06
TPDB_YES/LeikeHeizmann-TACAS2014-Ex9_true-termination.c,YES,,success,2.630481243133545,2025-05-23 03:46:09
TPDB_YES/nondet_ll_traverse-ptrdiff.c,ERROR,"[618738] Failed to execute script irankfinder
Traceback (most recent call last):
  File ""irankfinder.py"", line 190, in parse_file
  File ""genericparser/__init__.py"", line 109, in parse
  File ""genericparser/Parser_c.py"", line 25, in parse
  File ""genericparser/Parser_koat.py"", line 25, in parse_string
  File ""lark/lark.py"", line 197, in parse
  File ""lark/parser_frontends.py"", line 137, in parse
  File ""lark/parsers/xearley.py"", line 143, in parse
lark.common.ParseError: Unexpected end of input! Expecting a terminal of: ['__LPAR']

The above exception was the direct cause of the following exception:

Traceback (most recent call last):
  File ""irankfinder.py"", line 374, in <module>
  File ""irankfinder.py"", line 205, in launch
  File ""irankfinder.py"", line 197, in parse_file
Exception
",failed,0.3508903980255127,2025-05-23 03:46:09
TPDB_YES/svcomp_CookSeeZuleger-2013TACAS-Fig3_true-alloca.c,ERROR,"[618751] Failed to execute script irankfinder
Traceback (most recent call last):
  File ""irankfinder.py"", line 190, in parse_file
  File ""genericparser/__init__.py"", line 109, in parse
  File ""genericparser/Parser_c.py"", line 25, in parse
  File ""genericparser/Parser_koat.py"", line 25, in parse_string
  File ""lark/lark.py"", line 197, in parse
  File ""lark/parser_frontends.py"", line 137, in parse
  File ""lark/parsers/xearley.py"", line 143, in parse
lark.common.ParseError: Unexpected end of input! Expecting a terminal of: ['__LPAR']

The above exception was the direct cause of the following exception:

Traceback (most recent call last):
  File ""irankfinder.py"", line 374, in <module>
  File ""irankfinder.py"", line 205, in launch
  File ""irankfinder.py"", line 197, in parse_file
Exception
",failed,0.48489975929260254,2025-05-23 03:46:10
TPDB_YES/AliasDarteFeautrierGonnord-SAS2010-Fig2a_true-termination.c,MAYBE,,success,4.002140522003174,2025-05-23 03:46:14
TPDB_YES/svcomp_b.07-alloca.c,ERROR,"[618778] Failed to execute script irankfinder
Traceback (most recent call last):
  File ""irankfinder.py"", line 190, in parse_file
  File ""genericparser/__init__.py"", line 109, in parse
  File ""genericparser/Parser_c.py"", line 25, in parse
  File ""genericparser/Parser_koat.py"", line 25, in parse_string
  File ""lark/lark.py"", line 197, in parse
  File ""lark/parser_frontends.py"", line 137, in parse
  File ""lark/parsers/xearley.py"", line 143, in parse
lark.common.ParseError: Unexpected end of input! Expecting a terminal of: ['__LPAR']

The above exception was the direct cause of the following exception:

Traceback (most recent call last):
  File ""irankfinder.py"", line 374, in <module>
  File ""irankfinder.py"", line 205, in launch
  File ""irankfinder.py"", line 197, in parse_file
Exception
",failed,0.41488218307495117,2025-05-23 03:46:14
TPDB_YES/PastaB6.c,YES,,success,1.8100409507751465,2025-05-23 03:46:16
TPDB_YES/svcomp_insertionsort_alloca.c,ERROR,"[618805] Failed to execute script irankfinder
Traceback (most recent call last):
  File ""irankfinder.py"", line 190, in parse_file
  File ""genericparser/__init__.py"", line 109, in parse
  File ""genericparser/Parser_c.py"", line 25, in parse
  File ""genericparser/Parser_koat.py"", line 25, in parse_string
  File ""lark/lark.py"", line 197, in parse
  File ""lark/parser_frontends.py"", line 137, in parse
  File ""lark/parsers/xearley.py"", line 143, in parse
lark.common.ParseError: Unexpected end of input! Expecting a terminal of: ['__LPAR']

The above exception was the direct cause of the following exception:

Traceback (most recent call last):
  File ""irankfinder.py"", line 374, in <module>
  File ""irankfinder.py"", line 205, in launch
  File ""irankfinder.py"", line 197, in parse_file
Exception
",failed,0.35926342010498047,2025-05-23 03:46:16
TPDB_YES/Addition01_true-unreach-call_true-termination.c,ERROR,"[618818] Failed to execute script irankfinder
Traceback (most recent call last):
  File ""irankfinder.py"", line 190, in parse_file
  File ""genericparser/__init__.py"", line 109, in parse
  File ""genericparser/Parser_c.py"", line 21, in parse
Exception: b'Cannot use ""-eager-inline"" with a cyclic call hierarchy!\n'

The above exception was the direct cause of the following exception:

Traceback (most recent call last):
  File ""irankfinder.py"", line 374, in <module>
  File ""irankfinder.py"", line 205, in launch
  File ""irankfinder.py"", line 197, in parse_file
Exception
",failed,0.3335239887237549,2025-05-23 03:46:17
TPDB_YES/DivMinus2.c,MAYBE,,success,3.298234224319458,2025-05-23 03:46:20
TPDB_YES/LeikeHeizmann-WST2014-Ex9_true-termination.c,YES,,success,0.9735782146453857,2025-05-23 03:46:21
TPDB_YES/PastaB2.c,YES,,success,1.6761631965637207,2025-05-23 03:46:23
TPDB_YES/PastaB3.c,YES,,success,1.4985377788543701,2025-05-23 03:46:24
TPDB_YES/HeizmannHoenickeLeikePodelski-ATVA2013-Fig8_true-termination.c,MAYBE,,success,1.2176182270050049,2025-05-23 03:46:26
TPDB_YES/PastaA4.c,YES,,success,1.0135219097137451,2025-05-23 03:46:27
TPDB_YES/svcomp_BrockschmidtCookFuhs-2013CAV-Introduction_true-alloca.c,ERROR,"[618916] Failed to execute script irankfinder
Traceback (most recent call last):
  File ""irankfinder.py"", line 190, in parse_file
  File ""genericparser/__init__.py"", line 109, in parse
  File ""genericparser/Parser_c.py"", line 25, in parse
  File ""genericparser/Parser_koat.py"", line 25, in parse_string
  File ""lark/lark.py"", line 197, in parse
  File ""lark/parser_frontends.py"", line 137, in parse
  File ""lark/parsers/xearley.py"", line 143, in parse
lark.common.ParseError: Unexpected end of input! Expecting a terminal of: ['__LPAR']

The above exception was the direct cause of the following exception:

Traceback (most recent call last):
  File ""irankfinder.py"", line 374, in <module>
  File ""irankfinder.py"", line 205, in launch
  File ""irankfinder.py"", line 197, in parse_file
Exception
",failed,0.34958386421203613,2025-05-23 03:46:27
TPDB_YES/svcomp_stroeder2_alloca.c,ERROR,"[618929] Failed to execute script irankfinder
Traceback (most recent call last):
  File ""irankfinder.py"", line 190, in parse_file
  File ""genericparser/__init__.py"", line 109, in parse
  File ""genericparser/Parser_c.py"", line 25, in parse
  File ""genericparser/Parser_koat.py"", line 25, in parse_string
  File ""lark/lark.py"", line 197, in parse
  File ""lark/parser_frontends.py"", line 137, in parse
  File ""lark/parsers/xearley.py"", line 143, in parse
lark.common.ParseError: Unexpected end of input! Expecting a terminal of: ['__LPAR']

The above exception was the direct cause of the following exception:

Traceback (most recent call last):
  File ""irankfinder.py"", line 374, in <module>
  File ""irankfinder.py"", line 205, in launch
  File ""irankfinder.py"", line 197, in parse_file
Exception
",failed,0.48075127601623535,2025-05-23 03:46:27
TPDB_YES/genady_true-termination.c,MAYBE,,success,1.189676284790039,2025-05-23 03:46:29
TPDB_YES/Thun_true-termination.c,MAYBE,,success,1.5667707920074463,2025-05-23 03:46:30
TPDB_YES/svcomp_cstrcspn_true_alloca.c,ERROR,"[618970] Failed to execute script irankfinder
Traceback (most recent call last):
  File ""irankfinder.py"", line 190, in parse_file
  File ""genericparser/__init__.py"", line 109, in parse
  File ""genericparser/Parser_c.py"", line 25, in parse
  File ""genericparser/Parser_koat.py"", line 25, in parse_string
  File ""lark/lark.py"", line 197, in parse
  File ""lark/parser_frontends.py"", line 137, in parse
  File ""lark/parsers/xearley.py"", line 143, in parse
lark.common.ParseError: Unexpected end of input! Expecting a terminal of: ['__LPAR']

The above exception was the direct cause of the following exception:

Traceback (most recent call last):
  File ""irankfinder.py"", line 374, in <module>
  File ""irankfinder.py"", line 205, in launch
  File ""irankfinder.py"", line 197, in parse_file
Exception
",failed,0.4844677448272705,2025-05-23 03:46:31
TPDB_YES/svcomp_openbsd_cbzero_alloca.c,ERROR,"[618983] Failed to execute script irankfinder
Traceback (most recent call last):
  File ""irankfinder.py"", line 190, in parse_file
  File ""genericparser/__init__.py"", line 109, in parse
  File ""genericparser/Parser_c.py"", line 25, in parse
  File ""genericparser/Parser_koat.py"", line 25, in parse_string
  File ""lark/lark.py"", line 197, in parse
  File ""lark/parser_frontends.py"", line 137, in parse
  File ""lark/parsers/xearley.py"", line 143, in parse
lark.common.ParseError: Unexpected end of input! Expecting a terminal of: ['__LPAR']

The above exception was the direct cause of the following exception:

Traceback (most recent call last):
  File ""irankfinder.py"", line 374, in <module>
  File ""irankfinder.py"", line 205, in launch
  File ""irankfinder.py"", line 197, in parse_file
Exception
",failed,0.3587465286254883,2025-05-23 03:46:31
TPDB_YES/svcomp_Urban-2013WST-Fig2_true-alloca.c,ERROR,"[618996] Failed to execute script irankfinder
Traceback (most recent call last):
  File ""irankfinder.py"", line 190, in parse_file
  File ""genericparser/__init__.py"", line 109, in parse
  File ""genericparser/Parser_c.py"", line 25, in parse
  File ""genericparser/Parser_koat.py"", line 25, in parse_string
  File ""lark/lark.py"", line 197, in parse
  File ""lark/parser_frontends.py"", line 137, in parse
  File ""lark/parsers/xearley.py"", line 143, in parse
lark.common.ParseError: Unexpected end of input! Expecting a terminal of: ['__LPAR']

The above exception was the direct cause of the following exception:

Traceback (most recent call last):
  File ""irankfinder.py"", line 374, in <module>
  File ""irankfinder.py"", line 205, in launch
  File ""irankfinder.py"", line 197, in parse_file
Exception
",failed,0.3526439666748047,2025-05-23 03:46:31
TPDB_YES/SyntaxSupportPointer01_true-termination.c,ERROR,"[619009] Failed to execute script irankfinder
Traceback (most recent call last):
  File ""irankfinder.py"", line 190, in parse_file
  File ""genericparser/__init__.py"", line 109, in parse
  File ""genericparser/Parser_c.py"", line 25, in parse
  File ""genericparser/Parser_koat.py"", line 25, in parse_string
  File ""lark/lark.py"", line 197, in parse
  File ""lark/parser_frontends.py"", line 137, in parse
  File ""lark/parsers/xearley.py"", line 143, in parse
lark.common.ParseError: Unexpected end of input! Expecting a terminal of: ['__LPAR']

The above exception was the direct cause of the following exception:

Traceback (most recent call last):
  File ""irankfinder.py"", line 374, in <module>
  File ""irankfinder.py"", line 205, in launch
  File ""irankfinder.py"", line 197, in parse_file
Exception
",failed,0.48138880729675293,2025-05-23 03:46:32
TPDB_YES/ChenFlurMukhopadhyay-SAS2012-Ex2.16_true-termination.c,MAYBE,,success,1.030956506729126,2025-05-23 03:46:33
TPDB_YES/RecursiveMultiplication_true-termination.c,ERROR,"[619036] Failed to execute script irankfinder
Traceback (most recent call last):
  File ""irankfinder.py"", line 190, in parse_file
  File ""genericparser/__init__.py"", line 109, in parse
  File ""genericparser/Parser_c.py"", line 21, in parse
Exception: b'Cannot use ""-eager-inline"" with a cyclic call hierarchy!\n'

The above exception was the direct cause of the following exception:

Traceback (most recent call last):
  File ""irankfinder.py"", line 374, in <module>
  File ""irankfinder.py"", line 205, in launch
  File ""irankfinder.py"", line 197, in parse_file
Exception
",failed,0.45217394828796387,2025-05-23 03:46:33
TPDB_YES/svcomp_Avery-2006FLOPS-Tabel1_true-alloca.c,ERROR,"[619050] Failed to execute script irankfinder
Traceback (most recent call last):
  File ""irankfinder.py"", line 190, in parse_file
  File ""genericparser/__init__.py"", line 109, in parse
  File ""genericparser/Parser_c.py"", line 25, in parse
  File ""genericparser/Parser_koat.py"", line 25, in parse_string
  File ""lark/lark.py"", line 197, in parse
  File ""lark/parser_frontends.py"", line 137, in parse
  File ""lark/parsers/xearley.py"", line 143, in parse
lark.common.ParseError: Unexpected end of input! Expecting a terminal of: ['__LPAR']

The above exception was the direct cause of the following exception:

Traceback (most recent call last):
  File ""irankfinder.py"", line 374, in <module>
  File ""irankfinder.py"", line 205, in launch
  File ""irankfinder.py"", line 197, in parse_file
Exception
",failed,0.4840726852416992,2025-05-23 03:46:34
TPDB_YES/PastaC2.c,MAYBE,,success,1.5575237274169922,2025-05-23 03:46:35
TPDB_YES/svcomp_b.04-alloca.c,ERROR,"[619077] Failed to execute script irankfinder
Traceback (most recent call last):
  File ""irankfinder.py"", line 190, in parse_file
  File ""genericparser/__init__.py"", line 109, in parse
  File ""genericparser/Parser_c.py"", line 25, in parse
  File ""genericparser/Parser_koat.py"", line 25, in parse_string
  File ""lark/lark.py"", line 197, in parse
  File ""lark/parser_frontends.py"", line 137, in parse
  File ""lark/parsers/xearley.py"", line 143, in parse
lark.common.ParseError: Unexpected end of input! Expecting a terminal of: ['__LPAR']

The above exception was the direct cause of the following exception:

Traceback (most recent call last):
  File ""irankfinder.py"", line 374, in <module>
  File ""irankfinder.py"", line 205, in launch
  File ""irankfinder.py"", line 197, in parse_file
Exception
",failed,0.3533952236175537,2025-05-23 03:46:36
TPDB_YES/svcomp_c.07.c,YES,,success,1.934359073638916,2025-05-23 03:46:38
TPDB_YES/UrbanMine-ESOP2014-Fig3_true-termination.c,MAYBE,,success,5.833825588226318,2025-05-23 03:46:44
TPDB_YES/LeeJonesBen-Amram-POPL2001-Ex4_true-termination.c,ERROR,"[619118] Failed to execute script irankfinder
Traceback (most recent call last):
  File ""irankfinder.py"", line 190, in parse_file
  File ""genericparser/__init__.py"", line 109, in parse
  File ""genericparser/Parser_c.py"", line 21, in parse
Exception: b'Cannot use ""-eager-inline"" with a cyclic call hierarchy!\n'

The above exception was the direct cause of the following exception:

Traceback (most recent call last):
  File ""irankfinder.py"", line 374, in <module>
  File ""irankfinder.py"", line 205, in launch
  File ""irankfinder.py"", line 197, in parse_file
Exception
",failed,0.33772754669189453,2025-05-23 03:46:44
TPDB_YES/svcomp_a.04.c,YES,,success,1.1469144821166992,2025-05-23 03:46:45
TPDB_YES/svcomp_easySum.c,YES,,success,1.5843265056610107,2025-05-23 03:46:47
TPDB_YES/ChenFlurMukhopadhyay-SAS2012-Ex3.01_true-termination.c,MAYBE,,success,1.1950838565826416,2025-05-23 03:46:48
TPDB_YES/svcomp_b.04.c,YES,,success,1.0417075157165527,2025-05-23 03:46:49
TPDB_YES/GulavaniGulwani-CAV2008-Fig1c_true-termination.c,YES,,success,1.3189187049865723,2025-05-23 03:46:50
TPDB_YES/gcd1_true-termination.c,MAYBE,,success,2.406093120574951,2025-05-23 03:46:53
TPDB_YES/sum_2x3_false-unreach-call.c,ERROR,"[619216] Failed to execute script irankfinder
Traceback (most recent call last):
  File ""irankfinder.py"", line 190, in parse_file
  File ""genericparser/__init__.py"", line 109, in parse
  File ""genericparser/Parser_c.py"", line 21, in parse
Exception: b'Cannot use ""-eager-inline"" with a cyclic call hierarchy!\n'

The above exception was the direct cause of the following exception:

Traceback (most recent call last):
  File ""irankfinder.py"", line 374, in <module>
  File ""irankfinder.py"", line 205, in launch
  File ""irankfinder.py"", line 197, in parse_file
Exception
",failed,0.45776820182800293,2025-05-23 03:46:53
TPDB_YES/svcomp_b.09-no-inv_assume-alloca.c,ERROR,"[619230] Failed to execute script irankfinder
Traceback (most recent call last):
  File ""irankfinder.py"", line 190, in parse_file
  File ""genericparser/__init__.py"", line 109, in parse
  File ""genericparser/Parser_c.py"", line 25, in parse
  File ""genericparser/Parser_koat.py"", line 25, in parse_string
  File ""lark/lark.py"", line 197, in parse
  File ""lark/parser_frontends.py"", line 137, in parse
  File ""lark/parsers/xearley.py"", line 143, in parse
lark.common.ParseError: Unexpected end of input! Expecting a terminal of: ['__LPAR']

The above exception was the direct cause of the following exception:

Traceback (most recent call last):
  File ""irankfinder.py"", line 374, in <module>
  File ""irankfinder.py"", line 205, in launch
  File ""irankfinder.py"", line 197, in parse_file
Exception
",failed,0.477186918258667,2025-05-23 03:46:54
TPDB_YES/standard_copy7_true-unreach-call_ground.c,MAYBE,,success,23.998204469680786,2025-05-23 03:47:18
TPDB_YES/svcomp_a.06-alloca.c,ERROR,"[619257] Failed to execute script irankfinder
Traceback (most recent call last):
  File ""irankfinder.py"", line 190, in parse_file
  File ""genericparser/__init__.py"", line 109, in parse
  File ""genericparser/Parser_c.py"", line 25, in parse
  File ""genericparser/Parser_koat.py"", line 25, in parse_string
  File ""lark/lark.py"", line 197, in parse
  File ""lark/parser_frontends.py"", line 137, in parse
  File ""lark/parsers/xearley.py"", line 143, in parse
lark.common.ParseError: Unexpected end of input! Expecting a terminal of: ['__LPAR']

The above exception was the direct cause of the following exception:

Traceback (most recent call last):
  File ""irankfinder.py"", line 374, in <module>
  File ""irankfinder.py"", line 205, in launch
  File ""irankfinder.py"", line 197, in parse_file
Exception
",failed,0.48563385009765625,2025-05-23 03:47:18
TPDB_YES/LeeJonesBen-Amram-POPL2001-Ex1_true-termination.c,ERROR,"[619270] Failed to execute script irankfinder
Traceback (most recent call last):
  File ""irankfinder.py"", line 190, in parse_file
  File ""genericparser/__init__.py"", line 109, in parse
  File ""genericparser/Parser_c.py"", line 21, in parse
Exception: b'Cannot use ""-eager-inline"" with a cyclic call hierarchy!\n'

The above exception was the direct cause of the following exception:

Traceback (most recent call last):
  File ""irankfinder.py"", line 374, in <module>
  File ""irankfinder.py"", line 205, in launch
  File ""irankfinder.py"", line 197, in parse_file
Exception
",failed,0.3403658866882324,2025-05-23 03:47:19
TPDB_YES/NoriSharma-FSE2013-Fig7_true-termination.c,MAYBE,,success,2.3185646533966064,2025-05-23 03:47:21
TPDB_YES/svcomp_b.03-no-inv_assume-alloca.c,ERROR,"[619298] Failed to execute script irankfinder
Traceback (most recent call last):
  File ""irankfinder.py"", line 190, in parse_file
  File ""genericparser/__init__.py"", line 109, in parse
  File ""genericparser/Parser_c.py"", line 25, in parse
  File ""genericparser/Parser_koat.py"", line 25, in parse_string
  File ""lark/lark.py"", line 197, in parse
  File ""lark/parser_frontends.py"", line 137, in parse
  File ""lark/parsers/xearley.py"", line 143, in parse
lark.common.ParseError: Unexpected end of input! Expecting a terminal of: ['__LPAR']

The above exception was the direct cause of the following exception:

Traceback (most recent call last):
  File ""irankfinder.py"", line 374, in <module>
  File ""irankfinder.py"", line 205, in launch
  File ""irankfinder.py"", line 197, in parse_file
Exception
",failed,0.3627431392669678,2025-05-23 03:47:21
TPDB_YES/svcomp_cstrlen_true_alloca.c,ERROR,"[619311] Failed to execute script irankfinder
Traceback (most recent call last):
  File ""irankfinder.py"", line 190, in parse_file
  File ""genericparser/__init__.py"", line 109, in parse
  File ""genericparser/Parser_c.py"", line 25, in parse
  File ""genericparser/Parser_koat.py"", line 25, in parse_string
  File ""lark/lark.py"", line 197, in parse
  File ""lark/parser_frontends.py"", line 137, in parse
  File ""lark/parsers/xearley.py"", line 143, in parse
lark.common.ParseError: Unexpected end of input! Expecting a terminal of: ['__LPAR']

The above exception was the direct cause of the following exception:

Traceback (most recent call last):
  File ""irankfinder.py"", line 374, in <module>
  File ""irankfinder.py"", line 205, in launch
  File ""irankfinder.py"", line 197, in parse_file
Exception
",failed,0.47949671745300293,2025-05-23 03:47:22
TPDB_YES/ChenFlurMukhopadhyay-SAS2012-Ex3.05_true-termination.c,MAYBE,,success,1.3942339420318604,2025-05-23 03:47:23
TPDB_YES/ColonSipma-TACAS2001-Fig1_true-termination.c,YES,,success,2.1398308277130127,2025-05-23 03:47:25
TPDB_YES/svcomp_openbsd_cstrlen_alloca.c,ERROR,"[619352] Failed to execute script irankfinder
Traceback (most recent call last):
  File ""irankfinder.py"", line 190, in parse_file
  File ""genericparser/__init__.py"", line 109, in parse
  File ""genericparser/Parser_c.py"", line 25, in parse
  File ""genericparser/Parser_koat.py"", line 25, in parse_string
  File ""lark/lark.py"", line 197, in parse
  File ""lark/parser_frontends.py"", line 137, in parse
  File ""lark/parsers/xearley.py"", line 143, in parse
lark.common.ParseError: Unexpected end of input! Expecting a terminal of: ['__LPAR']

The above exception was the direct cause of the following exception:

Traceback (most recent call last):
  File ""irankfinder.py"", line 374, in <module>
  File ""irankfinder.py"", line 205, in launch
  File ""irankfinder.py"", line 197, in parse_file
Exception
",failed,0.35993432998657227,2025-05-23 03:47:26
TPDB_YES/GulwaniJainKoskinen-PLDI2009-Fig1_true-termination.c,MAYBE,,success,2.9245877265930176,2025-05-23 03:47:29
TPDB_YES/svcomp_b.14-alloca.c,ERROR,"[619379] Failed to execute script irankfinder
Traceback (most recent call last):
  File ""irankfinder.py"", line 190, in parse_file
  File ""genericparser/__init__.py"", line 109, in parse
  File ""genericparser/Parser_c.py"", line 25, in parse
  File ""genericparser/Parser_koat.py"", line 25, in parse_string
  File ""lark/lark.py"", line 197, in parse
  File ""lark/parser_frontends.py"", line 137, in parse
  File ""lark/parsers/xearley.py"", line 143, in parse
lark.common.ParseError: Unexpected end of input! Expecting a terminal of: ['__LPAR']

The above exception was the direct cause of the following exception:

Traceback (most recent call last):
  File ""irankfinder.py"", line 374, in <module>
  File ""irankfinder.py"", line 205, in launch
  File ""irankfinder.py"", line 197, in parse_file
Exception
",failed,0.4820244312286377,2025-05-23 03:47:29
TPDB_YES/ChenFlurMukhopadhyay-SAS2012-Ex1.05_true-termination.c,YES,,success,1.6978209018707275,2025-05-23 03:47:31
TPDB_YES/HarrisLalNoriRajamani-SAS2010-Fig1_true-termination.c,MAYBE,,success,18.38115930557251,2025-05-23 03:47:49
TPDB_YES/960521-1_1_true-valid-memsafety.c,MAYBE,,success,13.814788341522217,2025-05-23 03:48:03
TPDB_YES/svcomp_openbsd_cstrstr_alloca.c,ERROR,"[619434] Failed to execute script irankfinder
Traceback (most recent call last):
  File ""irankfinder.py"", line 190, in parse_file
  File ""genericparser/__init__.py"", line 109, in parse
  File ""genericparser/Parser_c.py"", line 25, in parse
  File ""genericparser/Parser_koat.py"", line 25, in parse_string
  File ""lark/lark.py"", line 197, in parse
  File ""lark/parser_frontends.py"", line 137, in parse
  File ""lark/parsers/xearley.py"", line 143, in parse
lark.common.ParseError: Unexpected end of input! Expecting a terminal of: ['__LPAR']

The above exception was the direct cause of the following exception:

Traceback (most recent call last):
  File ""irankfinder.py"", line 374, in <module>
  File ""irankfinder.py"", line 205, in launch
  File ""irankfinder.py"", line 197, in parse_file
Exception
",failed,0.47902750968933105,2025-05-23 03:48:04
TPDB_YES/Masse-VMCAI2014-Ex6_true-termination.c,MAYBE,,success,1.3154466152191162,2025-05-23 03:48:05
TPDB_YES/BrockschmidtCookFuhs-CAV2013-Introduction_true-termination.c,MAYBE,,success,1.6658222675323486,2025-05-23 03:48:07
TPDB_YES/svcomp_b.14.c,MAYBE,,success,2.779907464981079,2025-05-23 03:48:09
TPDB_YES/svcomp_b.02-alloca.c,ERROR,"[619489] Failed to execute script irankfinder
Traceback (most recent call last):
  File ""irankfinder.py"", line 190, in parse_file
  File ""genericparser/__init__.py"", line 109, in parse
  File ""genericparser/Parser_c.py"", line 25, in parse
  File ""genericparser/Parser_koat.py"", line 25, in parse_string
  File ""lark/lark.py"", line 197, in parse
  File ""lark/parser_frontends.py"", line 137, in parse
  File ""lark/parsers/xearley.py"", line 143, in parse
lark.common.ParseError: Unexpected end of input! Expecting a terminal of: ['__LPAR']

The above exception was the direct cause of the following exception:

Traceback (most recent call last):
  File ""irankfinder.py"", line 374, in <module>
  File ""irankfinder.py"", line 205, in launch
  File ""irankfinder.py"", line 197, in parse_file
Exception
",failed,0.48580312728881836,2025-05-23 03:48:10
TPDB_YES/svcomp_b.09-no-inv_assume.c,MAYBE,,success,1.9031860828399658,2025-05-23 03:48:12
TPDB_YES/MutualRecursion_1b_true-termination.c,ERROR,"[619516] Failed to execute script irankfinder
Traceback (most recent call last):
  File ""irankfinder.py"", line 190, in parse_file
  File ""genericparser/__init__.py"", line 109, in parse
  File ""genericparser/Parser_c.py"", line 21, in parse
Exception: b'/root/term/irankfinder-exe/genericparser/bin/c2koat: line 14: 619526 Segmentation fault      (core dumped) LD_LIBRARY_PATH=""$BASE:$LD_LIBRARY_PATH"" $BASE/llvm2kittel --dump-ll --no-slicing --eager-inline $TMPDIR/$NAME.bc -uniform-complexity-tuples\n'

The above exception was the direct cause of the following exception:

Traceback (most recent call last):
  File ""irankfinder.py"", line 374, in <module>
  File ""irankfinder.py"", line 205, in launch
  File ""irankfinder.py"", line 197, in parse_file
Exception
",failed,19.37058162689209,2025-05-23 03:48:31
TPDB_YES/nondet_ll_skip.c,ERROR,"[619530] Failed to execute script irankfinder
Traceback (most recent call last):
  File ""irankfinder.py"", line 190, in parse_file
  File ""genericparser/__init__.py"", line 109, in parse
  File ""genericparser/Parser_c.py"", line 25, in parse
  File ""genericparser/Parser_koat.py"", line 25, in parse_string
  File ""lark/lark.py"", line 197, in parse
  File ""lark/parser_frontends.py"", line 137, in parse
  File ""lark/parsers/xearley.py"", line 143, in parse
lark.common.ParseError: Unexpected end of input! Expecting a terminal of: ['__LPAR']

The above exception was the direct cause of the following exception:

Traceback (most recent call last):
  File ""irankfinder.py"", line 374, in <module>
  File ""irankfinder.py"", line 205, in launch
  File ""irankfinder.py"", line 197, in parse_file
Exception
",failed,0.4736602306365967,2025-05-23 03:48:32
TPDB_YES/svcomp_ex3a-alloca.c,ERROR,"[619543] Failed to execute script irankfinder
Traceback (most recent call last):
  File ""irankfinder.py"", line 190, in parse_file
  File ""genericparser/__init__.py"", line 109, in parse
  File ""genericparser/Parser_c.py"", line 25, in parse
  File ""genericparser/Parser_koat.py"", line 25, in parse_string
  File ""lark/lark.py"", line 197, in parse
  File ""lark/parser_frontends.py"", line 137, in parse
  File ""lark/parsers/xearley.py"", line 143, in parse
lark.common.ParseError: Unexpected end of input! Expecting a terminal of: ['__LPAR']

The above exception was the direct cause of the following exception:

Traceback (most recent call last):
  File ""irankfinder.py"", line 374, in <module>
  File ""irankfinder.py"", line 205, in launch
  File ""irankfinder.py"", line 197, in parse_file
Exception
",failed,0.4792346954345703,2025-05-23 03:48:32
TPDB_YES/HarrisLalNoriRajamani-SAS2010-Fig3_true-termination.c,YES,,success,1.9251046180725098,2025-05-23 03:48:34
TPDB_YES/afterrec_2calls_false-unreach-call.c,ERROR,"[619570] Failed to execute script irankfinder
Traceback (most recent call last):
  File ""irankfinder.py"", line 190, in parse_file
  File ""genericparser/__init__.py"", line 109, in parse
  File ""genericparser/Parser_c.py"", line 21, in parse
Exception: b'Cannot use ""-eager-inline"" with a cyclic call hierarchy!\n'

The above exception was the direct cause of the following exception:

Traceback (most recent call last):
  File ""irankfinder.py"", line 374, in <module>
  File ""irankfinder.py"", line 205, in launch
  File ""irankfinder.py"", line 197, in parse_file
Exception
",failed,0.3375537395477295,2025-05-23 03:48:34
TPDB_YES/svcomp_gcd01_true-unreach-call_true-termination_modified.c,ERROR,"[619584] Failed to execute script irankfinder
Traceback (most recent call last):
  File ""irankfinder.py"", line 190, in parse_file
  File ""genericparser/__init__.py"", line 109, in parse
  File ""genericparser/Parser_c.py"", line 21, in parse
Exception: b'Cannot use ""-eager-inline"" with a cyclic call hierarchy!\n'

The above exception was the direct cause of the following exception:

Traceback (most recent call last):
  File ""irankfinder.py"", line 374, in <module>
  File ""irankfinder.py"", line 205, in launch
  File ""irankfinder.py"", line 197, in parse_file
Exception
",failed,0.33672523498535156,2025-05-23 03:48:35
TPDB_YES/TwoWay_true.c,ERROR,"[619598] Failed to execute script irankfinder
Traceback (most recent call last):
  File ""irankfinder.py"", line 190, in parse_file
  File ""genericparser/__init__.py"", line 109, in parse
  File ""genericparser/Parser_c.py"", line 21, in parse
Exception: b'Cannot use ""-eager-inline"" with a cyclic call hierarchy!\n'

The above exception was the direct cause of the following exception:

Traceback (most recent call last):
  File ""irankfinder.py"", line 374, in <module>
  File ""irankfinder.py"", line 205, in launch
  File ""irankfinder.py"", line 197, in parse_file
Exception
",failed,0.33260607719421387,2025-05-23 03:48:35
TPDB_YES/data_structures_set_multi_proc_false-unreach-call_ground.c,MAYBE,,success,22.117685556411743,2025-05-23 03:48:57
TPDB_YES/ChawdharyCookGulwaniSagivYang-ESOP2008-aaron4_true-termination.c,MAYBE,,success,15.23428201675415,2025-05-23 03:49:12
TPDB_YES/svcomp_c.01-no-inv-alloca.c,ERROR,"[619640] Failed to execute script irankfinder
Traceback (most recent call last):
  File ""irankfinder.py"", line 190, in parse_file
  File ""genericparser/__init__.py"", line 109, in parse
  File ""genericparser/Parser_c.py"", line 25, in parse
  File ""genericparser/Parser_koat.py"", line 25, in parse_string
  File ""lark/lark.py"", line 197, in parse
  File ""lark/parser_frontends.py"", line 137, in parse
  File ""lark/parsers/xearley.py"", line 143, in parse
lark.common.ParseError: Unexpected end of input! Expecting a terminal of: ['__LPAR']

The above exception was the direct cause of the following exception:

Traceback (most recent call last):
  File ""irankfinder.py"", line 374, in <module>
  File ""irankfinder.py"", line 205, in launch
  File ""irankfinder.py"", line 197, in parse_file
Exception
",failed,0.3537466526031494,2025-05-23 03:49:13
TPDB_YES/Sequence.c,MAYBE,,success,1.4349067211151123,2025-05-23 03:49:14
TPDB_YES/asc_ll_search_last.c,ERROR,"[619667] Failed to execute script irankfinder
Traceback (most recent call last):
  File ""irankfinder.py"", line 190, in parse_file
  File ""genericparser/__init__.py"", line 109, in parse
  File ""genericparser/Parser_c.py"", line 25, in parse
  File ""genericparser/Parser_koat.py"", line 25, in parse_string
  File ""lark/lark.py"", line 197, in parse
  File ""lark/parser_frontends.py"", line 137, in parse
  File ""lark/parsers/xearley.py"", line 143, in parse
lark.common.ParseError: Unexpected end of input! Expecting a terminal of: ['__LPAR']

The above exception was the direct cause of the following exception:

Traceback (most recent call last):
  File ""irankfinder.py"", line 374, in <module>
  File ""irankfinder.py"", line 205, in launch
  File ""irankfinder.py"", line 197, in parse_file
Exception
",failed,0.48439979553222656,2025-05-23 03:49:15
TPDB_YES/svcomp_c.02.c,MAYBE,,success,2.3433444499969482,2025-05-23 03:49:17
TPDB_YES/GCD4.c,YES,,success,2.3292956352233887,2025-05-23 03:49:19
TPDB_YES/KroeningSharyginaTsitovichWintersteiger-CAV2010-Fig1_true-termination.c,MAYBE,,success,2.2380595207214355,2025-05-23 03:49:22
TPDB_YES/svcomp_ex1.c,YES,,success,1.767707109451294,2025-05-23 03:49:23
TPDB_YES/Copenhagen_disj_true-termination.c,MAYBE,,success,1.6931016445159912,2025-05-23 03:49:25
TPDB_YES/svcomp_java_AG313.c,YES,,success,1.5394957065582275,2025-05-23 03:49:27
TPDB_YES/AliasDarteFeautrierGonnord-SAS2010-wise_true-termination.c,MAYBE,,success,2.0723559856414795,2025-05-23 03:49:29
TPDB_YES/AliasDarteFeautrierGonnord-SAS2010-terminate_true-termination.c,YES,,success,1.933823823928833,2025-05-23 03:49:31
TPDB_YES/GulavaniGulwani-CAV2008-Fig1b_true-termination.c,YES,,success,2.4926259517669678,2025-05-23 03:49:33
TPDB_YES/ChenFlurMukhopadhyay-SAS2012-Ex3.09_true-termination.c,MAYBE,,success,2.1783640384674072,2025-05-23 03:49:35
TPDB_YES/PastaC3.c,MAYBE,,success,1.6839299201965332,2025-05-23 03:49:37
TPDB_YES/BradleyMannaSipma-ICALP2005-Fig1_true-termination.c,MAYBE,,success,3.6890647411346436,2025-05-23 03:49:41
TPDB_YES/Gothenburg_v2_true-termination.c,YES,,success,2.5338735580444336,2025-05-23 03:49:43
TPDB_YES/svcomp_openbsd_cstpcpy_alloca.c,ERROR,"[619862] Failed to execute script irankfinder
Traceback (most recent call last):
  File ""irankfinder.py"", line 190, in parse_file
  File ""genericparser/__init__.py"", line 109, in parse
  File ""genericparser/Parser_c.py"", line 25, in parse
  File ""genericparser/Parser_koat.py"", line 25, in parse_string
  File ""lark/lark.py"", line 197, in parse
  File ""lark/parser_frontends.py"", line 137, in parse
  File ""lark/parsers/xearley.py"", line 143, in parse
lark.common.ParseError: Unexpected end of input! Expecting a terminal of: ['__LPAR']

The above exception was the direct cause of the following exception:

Traceback (most recent call last):
  File ""irankfinder.py"", line 374, in <module>
  File ""irankfinder.py"", line 205, in launch
  File ""irankfinder.py"", line 197, in parse_file
Exception
",failed,0.3536946773529053,2025-05-23 03:49:44
TPDB_YES/PodelskiRybalchenko-LICS2004-Fig2-TACAS2011-Fig3_true-termination.c,MAYBE,,success,2.702793598175049,2025-05-23 03:49:46
TPDB_YES/PastaB14.c,MAYBE,,success,1.7621452808380127,2025-05-23 03:49:48
TPDB_YES/svcomp_a.08.c,YES,,success,1.3163061141967773,2025-05-23 03:49:50
TPDB_YES/ChenFlurMukhopadhyay-SAS2012-Ex2.21_true-termination.c,MAYBE,,success,1.1450083255767822,2025-05-23 03:49:51
TPDB_YES/McCarthyIterative.c,MAYBE,,success,1.4577322006225586,2025-05-23 03:49:52
TPDB_YES/svcomp_b.17-alloca.c,ERROR,"[619945] Failed to execute script irankfinder
Traceback (most recent call last):
  File ""irankfinder.py"", line 190, in parse_file
  File ""genericparser/__init__.py"", line 109, in parse
  File ""genericparser/Parser_c.py"", line 25, in parse
  File ""genericparser/Parser_koat.py"", line 25, in parse_string
  File ""lark/lark.py"", line 197, in parse
  File ""lark/parser_frontends.py"", line 137, in parse
  File ""lark/parsers/xearley.py"", line 143, in parse
lark.common.ParseError: Unexpected end of input! Expecting a terminal of: ['__LPAR']

The above exception was the direct cause of the following exception:

Traceback (most recent call last):
  File ""irankfinder.py"", line 374, in <module>
  File ""irankfinder.py"", line 205, in launch
  File ""irankfinder.py"", line 197, in parse_file
Exception
",failed,0.3592648506164551,2025-05-23 03:49:53
TPDB_YES/nondet_ll_search_last_n.c,ERROR,"[619958] Failed to execute script irankfinder
Traceback (most recent call last):
  File ""irankfinder.py"", line 190, in parse_file
  File ""genericparser/__init__.py"", line 109, in parse
  File ""genericparser/Parser_c.py"", line 25, in parse
  File ""genericparser/Parser_koat.py"", line 25, in parse_string
  File ""lark/lark.py"", line 197, in parse
  File ""lark/parser_frontends.py"", line 137, in parse
  File ""lark/parsers/xearley.py"", line 143, in parse
lark.common.ParseError: Unexpected end of input! Expecting a terminal of: ['__LPAR']

The above exception was the direct cause of the following exception:

Traceback (most recent call last):
  File ""irankfinder.py"", line 374, in <module>
  File ""irankfinder.py"", line 205, in launch
  File ""irankfinder.py"", line 197, in parse_file
Exception
",failed,0.4782233238220215,2025-05-23 03:49:53
TPDB_YES/svcomp_b.07.c,YES,,success,2.2407631874084473,2025-05-23 03:49:55
TPDB_YES/svcomp_MultCommutative_true-unreach-call_true-termination_modified.c,ERROR,"[619985] Failed to execute script irankfinder
Traceback (most recent call last):
  File ""irankfinder.py"", line 190, in parse_file
  File ""genericparser/__init__.py"", line 109, in parse
  File ""genericparser/Parser_c.py"", line 21, in parse
Exception: b'Cannot use ""-eager-inline"" with a cyclic call hierarchy!\n'

The above exception was the direct cause of the following exception:

Traceback (most recent call last):
  File ""irankfinder.py"", line 374, in <module>
  File ""irankfinder.py"", line 205, in launch
  File ""irankfinder.py"", line 197, in parse_file
Exception
",failed,0.3411295413970947,2025-05-23 03:49:56
TPDB_YES/AliasDarteFeautrierGonnord-SAS2010-nestedLoop_true-termination.c,MAYBE,,success,4.81117057800293,2025-05-23 03:50:00
TPDB_YES/PlusSwap.c,MAYBE,,success,1.2994089126586914,2025-05-23 03:50:02
TPDB_YES/LeikeHeizmann-TACAS2014-Ex7_true-termination.c,MAYBE,,success,1.6095201969146729,2025-05-23 03:50:03
TPDB_YES/svcomp_java_BubbleSort_alloca.c,ERROR,"[620041] Failed to execute script irankfinder
Traceback (most recent call last):
  File ""irankfinder.py"", line 190, in parse_file
  File ""genericparser/__init__.py"", line 109, in parse
  File ""genericparser/Parser_c.py"", line 25, in parse
  File ""genericparser/Parser_koat.py"", line 25, in parse_string
  File ""lark/lark.py"", line 197, in parse
  File ""lark/parser_frontends.py"", line 137, in parse
  File ""lark/parsers/xearley.py"", line 143, in parse
lark.common.ParseError: Unexpected end of input! Expecting a terminal of: ['__LPAR']

The above exception was the direct cause of the following exception:

Traceback (most recent call last):
  File ""irankfinder.py"", line 374, in <module>
  File ""irankfinder.py"", line 205, in launch
  File ""irankfinder.py"", line 197, in parse_file
Exception
",failed,0.3560295104980469,2025-05-23 03:50:04
TPDB_YES/ChenFlurMukhopadhyay-SAS2012-Ex3.10_true-termination.c,MAYBE,,success,2.1417837142944336,2025-05-23 03:50:06
TPDB_YES/svcomp_a.09_assume-alloca.c,ERROR,"[620068] Failed to execute script irankfinder
Traceback (most recent call last):
  File ""irankfinder.py"", line 190, in parse_file
  File ""genericparser/__init__.py"", line 109, in parse
  File ""genericparser/Parser_c.py"", line 25, in parse
  File ""genericparser/Parser_koat.py"", line 25, in parse_string
  File ""lark/lark.py"", line 197, in parse
  File ""lark/parser_frontends.py"", line 137, in parse
  File ""lark/parsers/xearley.py"", line 143, in parse
lark.common.ParseError: Unexpected end of input! Expecting a terminal of: ['__LPAR']

The above exception was the direct cause of the following exception:

Traceback (most recent call last):
  File ""irankfinder.py"", line 374, in <module>
  File ""irankfinder.py"", line 205, in launch
  File ""irankfinder.py"", line 197, in parse_file
Exception
",failed,0.35655665397644043,2025-05-23 03:50:06
TPDB_YES/svcomp_CookSeeZuleger-2013TACAS-Fig7b_true-alloca.c,ERROR,"[620081] Failed to execute script irankfinder
Traceback (most recent call last):
  File ""irankfinder.py"", line 190, in parse_file
  File ""genericparser/__init__.py"", line 109, in parse
  File ""genericparser/Parser_c.py"", line 25, in parse
  File ""genericparser/Parser_koat.py"", line 25, in parse_string
  File ""lark/lark.py"", line 197, in parse
  File ""lark/parser_frontends.py"", line 137, in parse
  File ""lark/parsers/xearley.py"", line 143, in parse
lark.common.ParseError: Unexpected end of input! Expecting a terminal of: ['__LPAR']

The above exception was the direct cause of the following exception:

Traceback (most recent call last):
  File ""irankfinder.py"", line 374, in <module>
  File ""irankfinder.py"", line 205, in launch
  File ""irankfinder.py"", line 197, in parse_file
Exception
",failed,0.48114728927612305,2025-05-23 03:50:07
TPDB_YES/PastaB15.c,MAYBE,,success,1.9859519004821777,2025-05-23 03:50:09
TPDB_YES/PodelskiRybalchenko-LICS2004-Fig1_true-termination.c,MAYBE,,success,1.4936013221740723,2025-05-23 03:50:10
TPDB_YES/svcomp_selectionsort_alloca.c,ERROR,"[620122] Failed to execute script irankfinder
Traceback (most recent call last):
  File ""irankfinder.py"", line 190, in parse_file
  File ""genericparser/__init__.py"", line 109, in parse
  File ""genericparser/Parser_c.py"", line 25, in parse
  File ""genericparser/Parser_koat.py"", line 25, in parse_string
  File ""lark/lark.py"", line 197, in parse
  File ""lark/parser_frontends.py"", line 137, in parse
  File ""lark/parsers/xearley.py"", line 143, in parse
lark.common.ParseError: Unexpected end of input! Expecting a terminal of: ['__LPAR']

The above exception was the direct cause of the following exception:

Traceback (most recent call last):
  File ""irankfinder.py"", line 374, in <module>
  File ""irankfinder.py"", line 205, in launch
  File ""irankfinder.py"", line 197, in parse_file
Exception
",failed,0.3506128787994385,2025-05-23 03:50:11
TPDB_YES/svcomp_Addition01_true-unreach-call_true-termination_modified.c,ERROR,"[620135] Failed to execute script irankfinder
Traceback (most recent call last):
  File ""irankfinder.py"", line 190, in parse_file
  File ""genericparser/__init__.py"", line 109, in parse
  File ""genericparser/Parser_c.py"", line 21, in parse
Exception: b'Cannot use ""-eager-inline"" with a cyclic call hierarchy!\n'

The above exception was the direct cause of the following exception:

Traceback (most recent call last):
  File ""irankfinder.py"", line 374, in <module>
  File ""irankfinder.py"", line 205, in launch
  File ""irankfinder.py"", line 197, in parse_file
Exception
",failed,0.4518296718597412,2025-05-23 03:50:11
TPDB_YES/ChenFlurMukhopadhyay-SAS2012-Ex3.03_true-termination.c,MAYBE,,success,1.9937894344329834,2025-05-23 03:50:13
TPDB_YES/svcomp_cstrspn_true-termination.c,ERROR,"[620163] Failed to execute script irankfinder
Traceback (most recent call last):
  File ""irankfinder.py"", line 190, in parse_file
  File ""genericparser/__init__.py"", line 109, in parse
  File ""genericparser/Parser_c.py"", line 25, in parse
  File ""genericparser/Parser_koat.py"", line 25, in parse_string
  File ""lark/lark.py"", line 197, in parse
  File ""lark/parser_frontends.py"", line 137, in parse
  File ""lark/parsers/xearley.py"", line 143, in parse
lark.common.ParseError: Unexpected end of input! Expecting a terminal of: ['__LPAR']

The above exception was the direct cause of the following exception:

Traceback (most recent call last):
  File ""irankfinder.py"", line 374, in <module>
  File ""irankfinder.py"", line 205, in launch
  File ""irankfinder.py"", line 197, in parse_file
Exception
",failed,0.3519415855407715,2025-05-23 03:50:13
TPDB_YES/LogAG.c,YES,,success,2.8637466430664062,2025-05-23 03:50:16
TPDB_YES/svcomp_c.01_assume.c,MAYBE,,success,2.4436275959014893,2025-05-23 03:50:19
TPDB_YES/svcomp_array01_alloca.c,ERROR,"[620204] Failed to execute script irankfinder
Traceback (most recent call last):
  File ""irankfinder.py"", line 190, in parse_file
  File ""genericparser/__init__.py"", line 109, in parse
  File ""genericparser/Parser_c.py"", line 25, in parse
  File ""genericparser/Parser_koat.py"", line 25, in parse_string
  File ""lark/lark.py"", line 197, in parse
  File ""lark/parser_frontends.py"", line 137, in parse
  File ""lark/parsers/xearley.py"", line 143, in parse
lark.common.ParseError: Unexpected end of input! Expecting a terminal of: ['__LPAR']

The above exception was the direct cause of the following exception:

Traceback (most recent call last):
  File ""irankfinder.py"", line 374, in <module>
  File ""irankfinder.py"", line 205, in launch
  File ""irankfinder.py"", line 197, in parse_file
Exception
",failed,0.4335744380950928,2025-05-23 03:50:19
TPDB_YES/AliasDarteFeautrierGonnord-SAS2010-ndecr_true-termination.c,YES,,success,1.3374083042144775,2025-05-23 03:50:21
TPDB_YES/Mysore_true-termination.c,MAYBE,,success,1.658282995223999,2025-05-23 03:50:22
TPDB_YES/svcomp_ChenFlurMukhopadhyay-2012SAS-Fig1_true-alloca.c,ERROR,"[620245] Failed to execute script irankfinder
Traceback (most recent call last):
  File ""irankfinder.py"", line 190, in parse_file
  File ""genericparser/__init__.py"", line 109, in parse
  File ""genericparser/Parser_c.py"", line 25, in parse
  File ""genericparser/Parser_koat.py"", line 25, in parse_string
  File ""lark/lark.py"", line 197, in parse
  File ""lark/parser_frontends.py"", line 137, in parse
  File ""lark/parsers/xearley.py"", line 143, in parse
lark.common.ParseError: Unexpected end of input! Expecting a terminal of: ['__LPAR']

The above exception was the direct cause of the following exception:

Traceback (most recent call last):
  File ""irankfinder.py"", line 374, in <module>
  File ""irankfinder.py"", line 205, in launch
  File ""irankfinder.py"", line 197, in parse_file
Exception
",failed,0.35654187202453613,2025-05-23 03:50:23
TPDB_YES/svcomp_twisted-alloca.c,ERROR,"[620258] Failed to execute script irankfinder
Traceback (most recent call last):
  File ""irankfinder.py"", line 190, in parse_file
  File ""genericparser/__init__.py"", line 109, in parse
  File ""genericparser/Parser_c.py"", line 25, in parse
  File ""genericparser/Parser_koat.py"", line 25, in parse_string
  File ""lark/lark.py"", line 197, in parse
  File ""lark/parser_frontends.py"", line 137, in parse
  File ""lark/parsers/xearley.py"", line 143, in parse
lark.common.ParseError: Unexpected end of input! Expecting a terminal of: ['__LPAR']

The above exception was the direct cause of the following exception:

Traceback (most recent call last):
  File ""irankfinder.py"", line 374, in <module>
  File ""irankfinder.py"", line 205, in launch
  File ""irankfinder.py"", line 197, in parse_file
Exception
",failed,0.3527195453643799,2025-05-23 03:50:23
TPDB_YES/svcomp_cstrspn_true_alloca.c,ERROR,"[620271] Failed to execute script irankfinder
Traceback (most recent call last):
  File ""irankfinder.py"", line 190, in parse_file
  File ""genericparser/__init__.py"", line 109, in parse
  File ""genericparser/Parser_c.py"", line 25, in parse
  File ""genericparser/Parser_koat.py"", line 25, in parse_string
  File ""lark/lark.py"", line 197, in parse
  File ""lark/parser_frontends.py"", line 137, in parse
  File ""lark/parsers/xearley.py"", line 143, in parse
lark.common.ParseError: Unexpected end of input! Expecting a terminal of: ['__LPAR']

The above exception was the direct cause of the following exception:

Traceback (most recent call last):
  File ""irankfinder.py"", line 374, in <module>
  File ""irankfinder.py"", line 205, in launch
  File ""irankfinder.py"", line 197, in parse_file
Exception
",failed,0.4853994846343994,2025-05-23 03:50:23
TPDB_YES/NestedRecursion_1c_true-termination.c,ERROR,"[620284] Failed to execute script irankfinder
Traceback (most recent call last):
  File ""irankfinder.py"", line 190, in parse_file
  File ""genericparser/__init__.py"", line 109, in parse
  File ""genericparser/Parser_c.py"", line 21, in parse
Exception: b'Cannot use ""-eager-inline"" with a cyclic call hierarchy!\n'

The above exception was the direct cause of the following exception:

Traceback (most recent call last):
  File ""irankfinder.py"", line 374, in <module>
  File ""irankfinder.py"", line 205, in launch
  File ""irankfinder.py"", line 197, in parse_file
Exception
",failed,0.44422340393066406,2025-05-23 03:50:24
TPDB_YES/BrockschmidtCookFuhs-CAV2013-Fig1_true-termination.c,MAYBE,,success,1.7305080890655518,2025-05-23 03:50:26
TPDB_YES/ChenFlurMukhopadhyay-SAS2012-Ex1.02_true-termination.c,YES,,success,1.9681057929992676,2025-05-23 03:50:28
TPDB_YES/PodelskiRybalchenko-TACAS2011-Fig1_true-termination.c,YES,,success,0.8689975738525391,2025-05-23 03:50:29
TPDB_YES/svcomp_Fibonacci01_true-unreach-call_modified.c,ERROR,"[620340] Failed to execute script irankfinder
Traceback (most recent call last):
  File ""irankfinder.py"", line 190, in parse_file
  File ""genericparser/__init__.py"", line 109, in parse
  File ""genericparser/Parser_c.py"", line 21, in parse
Exception: b'Cannot use ""-eager-inline"" with a cyclic call hierarchy!\n'

The above exception was the direct cause of the following exception:

Traceback (most recent call last):
  File ""irankfinder.py"", line 374, in <module>
  File ""irankfinder.py"", line 205, in launch
  File ""irankfinder.py"", line 197, in parse_file
Exception
",failed,0.4481024742126465,2025-05-23 03:50:29
TPDB_YES/svcomp_b.01-alloca.c,ERROR,"[620354] Failed to execute script irankfinder
Traceback (most recent call last):
  File ""irankfinder.py"", line 190, in parse_file
  File ""genericparser/__init__.py"", line 109, in parse
  File ""genericparser/Parser_c.py"", line 25, in parse
  File ""genericparser/Parser_koat.py"", line 25, in parse_string
  File ""lark/lark.py"", line 197, in parse
  File ""lark/parser_frontends.py"", line 137, in parse
  File ""lark/parsers/xearley.py"", line 143, in parse
lark.common.ParseError: Unexpected end of input! Expecting a terminal of: ['__LPAR']

The above exception was the direct cause of the following exception:

Traceback (most recent call last):
  File ""irankfinder.py"", line 374, in <module>
  File ""irankfinder.py"", line 205, in launch
  File ""irankfinder.py"", line 197, in parse_file
Exception
",failed,0.46652936935424805,2025-05-23 03:50:29
TPDB_YES/svcomp_cstrcmp_true_alloca.c,ERROR,"[620367] Failed to execute script irankfinder
Traceback (most recent call last):
  File ""irankfinder.py"", line 190, in parse_file
  File ""genericparser/__init__.py"", line 109, in parse
  File ""genericparser/Parser_c.py"", line 25, in parse
  File ""genericparser/Parser_koat.py"", line 25, in parse_string
  File ""lark/lark.py"", line 197, in parse
  File ""lark/parser_frontends.py"", line 137, in parse
  File ""lark/parsers/xearley.py"", line 143, in parse
lark.common.ParseError: Unexpected end of input! Expecting a terminal of: ['__LPAR']

The above exception was the direct cause of the following exception:

Traceback (most recent call last):
  File ""irankfinder.py"", line 374, in <module>
  File ""irankfinder.py"", line 205, in launch
  File ""irankfinder.py"", line 197, in parse_file
Exception
",failed,0.48472094535827637,2025-05-23 03:50:30
TPDB_YES/4BitCounterPointer_true-termination.c,ERROR,"[620380] Failed to execute script irankfinder
Traceback (most recent call last):
  File ""irankfinder.py"", line 190, in parse_file
  File ""genericparser/__init__.py"", line 109, in parse
  File ""genericparser/Parser_c.py"", line 25, in parse
  File ""genericparser/Parser_koat.py"", line 25, in parse_string
  File ""lark/lark.py"", line 197, in parse
  File ""lark/parser_frontends.py"", line 137, in parse
  File ""lark/parsers/xearley.py"", line 143, in parse
lark.common.ParseError: Unexpected end of input! Expecting a terminal of: ['__LPAR']

The above exception was the direct cause of the following exception:

Traceback (most recent call last):
  File ""irankfinder.py"", line 374, in <module>
  File ""irankfinder.py"", line 205, in launch
  File ""irankfinder.py"", line 197, in parse_file
Exception
",failed,0.4874246120452881,2025-05-23 03:50:30
TPDB_YES/svcomp_b.10-alloca.c,ERROR,"[620393] Failed to execute script irankfinder
Traceback (most recent call last):
  File ""irankfinder.py"", line 190, in parse_file
  File ""genericparser/__init__.py"", line 109, in parse
  File ""genericparser/Parser_c.py"", line 25, in parse
  File ""genericparser/Parser_koat.py"", line 25, in parse_string
  File ""lark/lark.py"", line 197, in parse
  File ""lark/parser_frontends.py"", line 137, in parse
  File ""lark/parsers/xearley.py"", line 143, in parse
lark.common.ParseError: Unexpected end of input! Expecting a terminal of: ['__LPAR']

The above exception was the direct cause of the following exception:

Traceback (most recent call last):
  File ""irankfinder.py"", line 374, in <module>
  File ""irankfinder.py"", line 205, in launch
  File ""irankfinder.py"", line 197, in parse_file
Exception
",failed,0.4820082187652588,2025-05-23 03:50:31
TPDB_YES/AliasDarteFeautrierGonnord-SAS2010-counterex1a_true-termination.c,MAYBE,,success,6.409555196762085,2025-05-23 03:50:37
TPDB_YES/Bangalore_true-termination.c,YES,,success,1.5086300373077393,2025-05-23 03:50:39
TPDB_YES/Nyala-2lex_true-termination.c,MAYBE,,success,2.08243465423584,2025-05-23 03:50:41
TPDB_YES/Binomial_true.c,ERROR,"[620448] Failed to execute script irankfinder
Traceback (most recent call last):
  File ""irankfinder.py"", line 190, in parse_file
  File ""genericparser/__init__.py"", line 109, in parse
  File ""genericparser/Parser_c.py"", line 21, in parse
Exception: b'Cannot use ""-eager-inline"" with a cyclic call hierarchy!\n'

The above exception was the direct cause of the following exception:

Traceback (most recent call last):
  File ""irankfinder.py"", line 374, in <module>
  File ""irankfinder.py"", line 205, in launch
  File ""irankfinder.py"", line 197, in parse_file
Exception
",failed,0.4490032196044922,2025-05-23 03:50:41
TPDB_YES/Et2_true.c,ERROR,"[620462] Failed to execute script irankfinder
Traceback (most recent call last):
  File ""irankfinder.py"", line 190, in parse_file
  File ""genericparser/__init__.py"", line 109, in parse
  File ""genericparser/Parser_c.py"", line 21, in parse
Exception: b'Cannot use ""-eager-inline"" with a cyclic call hierarchy!\n'

The above exception was the direct cause of the following exception:

Traceback (most recent call last):
  File ""irankfinder.py"", line 374, in <module>
  File ""irankfinder.py"", line 205, in launch
  File ""irankfinder.py"", line 197, in parse_file
Exception
",failed,0.44484639167785645,2025-05-23 03:50:42
TPDB_YES/MenloPark_true-termination.c,YES,,success,1.776963472366333,2025-05-23 03:50:44
TPDB_YES/desc_ll_search_last.c,ERROR,"[620490] Failed to execute script irankfinder
Traceback (most recent call last):
  File ""irankfinder.py"", line 190, in parse_file
  File ""genericparser/__init__.py"", line 109, in parse
  File ""genericparser/Parser_c.py"", line 25, in parse
  File ""genericparser/Parser_koat.py"", line 25, in parse_string
  File ""lark/lark.py"", line 197, in parse
  File ""lark/parser_frontends.py"", line 137, in parse
  File ""lark/parsers/xearley.py"", line 143, in parse
lark.common.ParseError: Unexpected end of input! Expecting a terminal of: ['__LPAR']

The above exception was the direct cause of the following exception:

Traceback (most recent call last):
  File ""irankfinder.py"", line 374, in <module>
  File ""irankfinder.py"", line 205, in launch
  File ""irankfinder.py"", line 197, in parse_file
Exception
",failed,0.48601841926574707,2025-05-23 03:50:44
TPDB_YES/Copenhagen_true-termination.c,YES,,success,1.1958446502685547,2025-05-23 03:50:45
TPDB_YES/2Nested_true-termination.c,MAYBE,,success,1.0818660259246826,2025-05-23 03:50:46
TPDB_YES/Log.c,MAYBE,,success,2.129019021987915,2025-05-23 03:50:49
TPDB_YES/svcomp_Ben-Amram-2010LMCS-Ex2.3_true-alloca.c,ERROR,"[620545] Failed to execute script irankfinder
Traceback (most recent call last):
  File ""irankfinder.py"", line 190, in parse_file
  File ""genericparser/__init__.py"", line 109, in parse
  File ""genericparser/Parser_c.py"", line 25, in parse
  File ""genericparser/Parser_koat.py"", line 25, in parse_string
  File ""lark/lark.py"", line 197, in parse
  File ""lark/parser_frontends.py"", line 137, in parse
  File ""lark/parsers/xearley.py"", line 143, in parse
lark.common.ParseError: Unexpected end of input! Expecting a terminal of: ['__LPAR']

The above exception was the direct cause of the following exception:

Traceback (most recent call last):
  File ""irankfinder.py"", line 374, in <module>
  File ""irankfinder.py"", line 205, in launch
  File ""irankfinder.py"", line 197, in parse_file
Exception
",failed,0.35530924797058105,2025-05-23 03:50:49
TPDB_YES/CookSeeZuleger-TACAS2013-Fig8a-modified_true-termination.c,MAYBE,,success,1.8364863395690918,2025-05-23 03:50:51
TPDB_YES/ChenFlurMukhopadhyay-SAS2012-Ex2.13_true-termination.c,MAYBE,,success,1.1631920337677002,2025-05-23 03:50:52
TPDB_YES/aaron2_true-termination.c,YES,,success,2.8218371868133545,2025-05-23 03:50:55
TPDB_YES/IntPath.c,MAYBE,,success,1.278855562210083,2025-05-23 03:50:56
TPDB_YES/DivMinus.c,YES,,success,1.7362782955169678,2025-05-23 03:50:58
TPDB_YES/svcomp_openbsd_cmemchr_alloca.c,ERROR,"[620628] Failed to execute script irankfinder
Traceback (most recent call last):
  File ""irankfinder.py"", line 190, in parse_file
  File ""genericparser/__init__.py"", line 109, in parse
  File ""genericparser/Parser_c.py"", line 25, in parse
  File ""genericparser/Parser_koat.py"", line 25, in parse_string
  File ""lark/lark.py"", line 197, in parse
  File ""lark/parser_frontends.py"", line 137, in parse
  File ""lark/parsers/xearley.py"", line 143, in parse
lark.common.ParseError: Unexpected end of input! Expecting a terminal of: ['__LPAR']

The above exception was the direct cause of the following exception:

Traceback (most recent call last):
  File ""irankfinder.py"", line 374, in <module>
  File ""irankfinder.py"", line 205, in launch
  File ""irankfinder.py"", line 197, in parse_file
Exception
",failed,0.482318639755249,2025-05-23 03:50:58
TPDB_YES/svcomp_openbsd_cstrncmp_alloca.c,ERROR,"[620641] Failed to execute script irankfinder
Traceback (most recent call last):
  File ""irankfinder.py"", line 190, in parse_file
  File ""genericparser/__init__.py"", line 109, in parse
  File ""genericparser/Parser_c.py"", line 25, in parse
  File ""genericparser/Parser_koat.py"", line 25, in parse_string
  File ""lark/lark.py"", line 197, in parse
  File ""lark/parser_frontends.py"", line 137, in parse
  File ""lark/parsers/xearley.py"", line 143, in parse
lark.common.ParseError: Unexpected end of input! Expecting a terminal of: ['__LPAR']

The above exception was the direct cause of the following exception:

Traceback (most recent call last):
  File ""irankfinder.py"", line 374, in <module>
  File ""irankfinder.py"", line 205, in launch
  File ""irankfinder.py"", line 197, in parse_file
Exception
",failed,0.3538360595703125,2025-05-23 03:50:59
TPDB_YES/svcomp_HarrisLalNoriRajamani-2010SAS-Fig3_true-alloca.c,ERROR,"[620654] Failed to execute script irankfinder
Traceback (most recent call last):
  File ""irankfinder.py"", line 190, in parse_file
  File ""genericparser/__init__.py"", line 109, in parse
  File ""genericparser/Parser_c.py"", line 25, in parse
  File ""genericparser/Parser_koat.py"", line 25, in parse_string
  File ""lark/lark.py"", line 197, in parse
  File ""lark/parser_frontends.py"", line 137, in parse
  File ""lark/parsers/xearley.py"", line 143, in parse
lark.common.ParseError: Unexpected end of input! Expecting a terminal of: ['__LPAR']

The above exception was the direct cause of the following exception:

Traceback (most recent call last):
  File ""irankfinder.py"", line 374, in <module>
  File ""irankfinder.py"", line 205, in launch
  File ""irankfinder.py"", line 197, in parse_file
Exception
",failed,0.4797184467315674,2025-05-23 03:50:59
TPDB_YES/svcomp_c.03-alloca.c,ERROR,"[620667] Failed to execute script irankfinder
Traceback (most recent call last):
  File ""irankfinder.py"", line 190, in parse_file
  File ""genericparser/__init__.py"", line 109, in parse
  File ""genericparser/Parser_c.py"", line 25, in parse
  File ""genericparser/Parser_koat.py"", line 25, in parse_string
  File ""lark/lark.py"", line 197, in parse
  File ""lark/parser_frontends.py"", line 137, in parse
  File ""lark/parsers/xearley.py"", line 143, in parse
lark.common.ParseError: Unexpected end of input! Expecting a terminal of: ['__LPAR']

The above exception was the direct cause of the following exception:

Traceback (most recent call last):
  File ""irankfinder.py"", line 374, in <module>
  File ""irankfinder.py"", line 205, in launch
  File ""irankfinder.py"", line 197, in parse_file
Exception
",failed,0.47528767585754395,2025-05-23 03:51:00
TPDB_YES/aaron3_true-termination.c,ERROR,Execution timed out,failed,120,2025-05-23 03:53:00
TPDB_YES/svcomp_fermat.c,MAYBE,,success,5.896589756011963,2025-05-23 03:53:06
TPDB_YES/Arrays01-EquivalentConstantIndices_true-termination.c,MAYBE,,success,0.6901593208312988,2025-05-23 03:53:06
TPDB_YES/Piecewise_true-termination.c,MAYBE,,success,2.918951988220215,2025-05-23 03:53:09
TPDB_YES/svcomp_java_Nested.c,MAYBE,,success,1.5112462043762207,2025-05-23 03:53:11
TPDB_YES/svcomp_a.10.c,MAYBE,,success,1.9762217998504639,2025-05-23 03:53:13
TPDB_YES/LeeJonesBen-Amram-POPL2001-Ex3_true-termination.c,ERROR,"[620765] Failed to execute script irankfinder
Traceback (most recent call last):
  File ""irankfinder.py"", line 190, in parse_file
  File ""genericparser/__init__.py"", line 109, in parse
  File ""genericparser/Parser_c.py"", line 21, in parse
Exception: b'Cannot use ""-eager-inline"" with a cyclic call hierarchy!\n'

The above exception was the direct cause of the following exception:

Traceback (most recent call last):
  File ""irankfinder.py"", line 374, in <module>
  File ""irankfinder.py"", line 205, in launch
  File ""irankfinder.py"", line 197, in parse_file
Exception
",failed,0.45466136932373047,2025-05-23 03:53:13
TPDB_YES/svcomp_java_Sequence.c,MAYBE,,success,1.3520143032073975,2025-05-23 03:53:15
TPDB_YES/4NestedWith3Variables_true-termination.c,MAYBE,,success,1.749061107635498,2025-05-23 03:53:16
TPDB_YES/svcomp_b.17.c,MAYBE,,success,2.9814648628234863,2025-05-23 03:53:19
TPDB_YES/WhileFalse_true-termination.c,YES,,success,0.5431251525878906,2025-05-23 03:53:20
TPDB_YES/svcomp_a.01-alloca.c,ERROR,"[620835] Failed to execute script irankfinder
Traceback (most recent call last):
  File ""irankfinder.py"", line 190, in parse_file
  File ""genericparser/__init__.py"", line 109, in parse
  File ""genericparser/Parser_c.py"", line 25, in parse
  File ""genericparser/Parser_koat.py"", line 25, in parse_string
  File ""lark/lark.py"", line 197, in parse
  File ""lark/parser_frontends.py"", line 137, in parse
  File ""lark/parsers/xearley.py"", line 143, in parse
lark.common.ParseError: Unexpected end of input! Expecting a terminal of: ['__LPAR']

The above exception was the direct cause of the following exception:

Traceback (most recent call last):
  File ""irankfinder.py"", line 374, in <module>
  File ""irankfinder.py"", line 205, in launch
  File ""irankfinder.py"", line 197, in parse_file
Exception
",failed,0.47318196296691895,2025-05-23 03:53:20
TPDB_YES/nondet_ll_init.c,ERROR,"[620848] Failed to execute script irankfinder
Traceback (most recent call last):
  File ""irankfinder.py"", line 190, in parse_file
  File ""genericparser/__init__.py"", line 109, in parse
  File ""genericparser/Parser_c.py"", line 25, in parse
  File ""genericparser/Parser_koat.py"", line 25, in parse_string
  File ""lark/lark.py"", line 197, in parse
  File ""lark/parser_frontends.py"", line 137, in parse
  File ""lark/parsers/xearley.py"", line 143, in parse
lark.common.ParseError: Unexpected end of input! Expecting a terminal of: ['__LPAR']

The above exception was the direct cause of the following exception:

Traceback (most recent call last):
  File ""irankfinder.py"", line 374, in <module>
  File ""irankfinder.py"", line 205, in launch
  File ""irankfinder.py"", line 197, in parse_file
Exception
",failed,0.4786264896392822,2025-05-23 03:53:21
TPDB_YES/svcomp_a.06.c,YES,,success,2.274256944656372,2025-05-23 03:53:23
TPDB_YES/PastaA7.c,YES,,success,1.9125120639801025,2025-05-23 03:53:25
TPDB_YES/svcomp_b.13.c,MAYBE,,success,3.763192892074585,2025-05-23 03:53:29
TPDB_YES/svcomp_min_rf_true-alloca.c,ERROR,"[620903] Failed to execute script irankfinder
Traceback (most recent call last):
  File ""irankfinder.py"", line 190, in parse_file
  File ""genericparser/__init__.py"", line 109, in parse
  File ""genericparser/Parser_c.py"", line 25, in parse
  File ""genericparser/Parser_koat.py"", line 25, in parse_string
  File ""lark/lark.py"", line 197, in parse
  File ""lark/parser_frontends.py"", line 137, in parse
  File ""lark/parsers/xearley.py"", line 143, in parse
lark.common.ParseError: Unexpected end of input! Expecting a terminal of: ['__LPAR']

The above exception was the direct cause of the following exception:

Traceback (most recent call last):
  File ""irankfinder.py"", line 374, in <module>
  File ""irankfinder.py"", line 205, in launch
  File ""irankfinder.py"", line 197, in parse_file
Exception
",failed,0.349365234375,2025-05-23 03:53:29
TPDB_YES/ChenFlurMukhopadhyay-SAS2012-Ex2.08_true-termination.c,MAYBE,,success,1.1466846466064453,2025-05-23 03:53:30
TPDB_YES/svcomp_b.12-alloca.c,ERROR,"[620930] Failed to execute script irankfinder
Traceback (most recent call last):
  File ""irankfinder.py"", line 190, in parse_file
  File ""genericparser/__init__.py"", line 109, in parse
  File ""genericparser/Parser_c.py"", line 25, in parse
  File ""genericparser/Parser_koat.py"", line 25, in parse_string
  File ""lark/lark.py"", line 197, in parse
  File ""lark/parser_frontends.py"", line 137, in parse
  File ""lark/parsers/xearley.py"", line 143, in parse
lark.common.ParseError: Unexpected end of input! Expecting a terminal of: ['__LPAR']

The above exception was the direct cause of the following exception:

Traceback (most recent call last):
  File ""irankfinder.py"", line 374, in <module>
  File ""irankfinder.py"", line 205, in launch
  File ""irankfinder.py"", line 197, in parse_file
Exception
",failed,0.3528563976287842,2025-05-23 03:53:31
TPDB_YES/nondet_ll_init_rec.c,ERROR,"[620943] Failed to execute script irankfinder
Traceback (most recent call last):
  File ""irankfinder.py"", line 190, in parse_file
  File ""genericparser/__init__.py"", line 109, in parse
  File ""genericparser/Parser_c.py"", line 25, in parse
  File ""genericparser/Parser_koat.py"", line 25, in parse_string
  File ""lark/lark.py"", line 197, in parse
  File ""lark/parser_frontends.py"", line 137, in parse
  File ""lark/parsers/xearley.py"", line 143, in parse
lark.common.ParseError: Unexpected end of input! Expecting a terminal of: ['__LPAR']

The above exception was the direct cause of the following exception:

Traceback (most recent call last):
  File ""irankfinder.py"", line 374, in <module>
  File ""irankfinder.py"", line 205, in launch
  File ""irankfinder.py"", line 197, in parse_file
Exception
",failed,0.4187953472137451,2025-05-23 03:53:31
TPDB_YES/PastaB17.c,MAYBE,,success,1.9987118244171143,2025-05-23 03:53:33
TPDB_YES/Urban-WST2013-Fig2-modified1000_true-termination.c,MAYBE,,success,1.4893896579742432,2025-05-23 03:53:35
TPDB_YES/svcomp_count_down_alloca.c,ERROR,"[620984] Failed to execute script irankfinder
Traceback (most recent call last):
  File ""irankfinder.py"", line 190, in parse_file
  File ""genericparser/__init__.py"", line 109, in parse
  File ""genericparser/Parser_c.py"", line 25, in parse
  File ""genericparser/Parser_koat.py"", line 25, in parse_string
  File ""lark/lark.py"", line 197, in parse
  File ""lark/parser_frontends.py"", line 137, in parse
  File ""lark/parsers/xearley.py"", line 143, in parse
lark.common.ParseError: Unexpected end of input! Expecting a terminal of: ['__LPAR']

The above exception was the direct cause of the following exception:

Traceback (most recent call last):
  File ""irankfinder.py"", line 374, in <module>
  File ""irankfinder.py"", line 205, in launch
  File ""irankfinder.py"", line 197, in parse_file
Exception
",failed,0.48778605461120605,2025-05-23 03:53:35
TPDB_YES/svcomp_b.09_assume-alloca.c,ERROR,"[620997] Failed to execute script irankfinder
Traceback (most recent call last):
  File ""irankfinder.py"", line 190, in parse_file
  File ""genericparser/__init__.py"", line 109, in parse
  File ""genericparser/Parser_c.py"", line 25, in parse
  File ""genericparser/Parser_koat.py"", line 25, in parse_string
  File ""lark/lark.py"", line 197, in parse
  File ""lark/parser_frontends.py"", line 137, in parse
  File ""lark/parsers/xearley.py"", line 143, in parse
lark.common.ParseError: Unexpected end of input! Expecting a terminal of: ['__LPAR']

The above exception was the direct cause of the following exception:

Traceback (most recent call last):
  File ""irankfinder.py"", line 374, in <module>
  File ""irankfinder.py"", line 205, in launch
  File ""irankfinder.py"", line 197, in parse_file
Exception
",failed,0.3498725891113281,2025-05-23 03:53:36
TPDB_YES/svcomp_b.15.c,MAYBE,,success,3.317042350769043,2025-05-23 03:53:39
TPDB_YES/ChawdharyCookGulwaniSagivYang-ESOP2008-aaron1_true-termination.c,MAYBE,,success,8.452085971832275,2025-05-23 03:53:47
TPDB_YES/ChawdharyCookGulwaniSagivYang-ESOP2008-random2d_true-termination.c,MAYBE,,success,6.941692352294922,2025-05-23 03:53:54
TPDB_YES/svcomp_b.03_assume.c,YES,,success,1.1872427463531494,2025-05-23 03:53:56
TPDB_YES/svcomp_b.11-alloca.c,ERROR,"[621066] Failed to execute script irankfinder
Traceback (most recent call last):
  File ""irankfinder.py"", line 190, in parse_file
  File ""genericparser/__init__.py"", line 109, in parse
  File ""genericparser/Parser_c.py"", line 25, in parse
  File ""genericparser/Parser_koat.py"", line 25, in parse_string
  File ""lark/lark.py"", line 197, in parse
  File ""lark/parser_frontends.py"", line 137, in parse
  File ""lark/parsers/xearley.py"", line 143, in parse
lark.common.ParseError: Unexpected end of input! Expecting a terminal of: ['__LPAR']

The above exception was the direct cause of the following exception:

Traceback (most recent call last):
  File ""irankfinder.py"", line 374, in <module>
  File ""irankfinder.py"", line 205, in launch
  File ""irankfinder.py"", line 197, in parse_file
Exception
",failed,0.48243117332458496,2025-05-23 03:53:56
TPDB_YES/Et4_true.c,ERROR,"[621079] Failed to execute script irankfinder
Traceback (most recent call last):
  File ""irankfinder.py"", line 190, in parse_file
  File ""genericparser/__init__.py"", line 109, in parse
  File ""genericparser/Parser_c.py"", line 21, in parse
Exception: b'Cannot use ""-eager-inline"" with a cyclic call hierarchy!\n'

The above exception was the direct cause of the following exception:

Traceback (most recent call last):
  File ""irankfinder.py"", line 374, in <module>
  File ""irankfinder.py"", line 205, in launch
  File ""irankfinder.py"", line 197, in parse_file
Exception
",failed,0.333646297454834,2025-05-23 03:53:56
TPDB_YES/svcomp_openbsd_cstrspn_alloca.c,ERROR,"[621093] Failed to execute script irankfinder
Traceback (most recent call last):
  File ""irankfinder.py"", line 190, in parse_file
  File ""genericparser/__init__.py"", line 109, in parse
  File ""genericparser/Parser_c.py"", line 25, in parse
  File ""genericparser/Parser_koat.py"", line 25, in parse_string
  File ""lark/lark.py"", line 197, in parse
  File ""lark/parser_frontends.py"", line 137, in parse
  File ""lark/parsers/xearley.py"", line 143, in parse
lark.common.ParseError: Unexpected end of input! Expecting a terminal of: ['__LPAR']

The above exception was the direct cause of the following exception:

Traceback (most recent call last):
  File ""irankfinder.py"", line 374, in <module>
  File ""irankfinder.py"", line 205, in launch
  File ""irankfinder.py"", line 197, in parse_file
Exception
",failed,0.3505520820617676,2025-05-23 03:53:57
TPDB_YES/LeUserDefRec_true.c,ERROR,"[621106] Failed to execute script irankfinder
Traceback (most recent call last):
  File ""irankfinder.py"", line 190, in parse_file
  File ""genericparser/__init__.py"", line 109, in parse
  File ""genericparser/Parser_c.py"", line 21, in parse
Exception: b'Cannot use ""-eager-inline"" with a cyclic call hierarchy!\n'

The above exception was the direct cause of the following exception:

Traceback (most recent call last):
  File ""irankfinder.py"", line 374, in <module>
  File ""irankfinder.py"", line 205, in launch
  File ""irankfinder.py"", line 197, in parse_file
Exception
",failed,0.449843168258667,2025-05-23 03:53:57
TPDB_YES/svcomp_a.10-alloca.c,ERROR,"[621120] Failed to execute script irankfinder
Traceback (most recent call last):
  File ""irankfinder.py"", line 190, in parse_file
  File ""genericparser/__init__.py"", line 109, in parse
  File ""genericparser/Parser_c.py"", line 25, in parse
  File ""genericparser/Parser_koat.py"", line 25, in parse_string
  File ""lark/lark.py"", line 197, in parse
  File ""lark/parser_frontends.py"", line 137, in parse
  File ""lark/parsers/xearley.py"", line 143, in parse
lark.common.ParseError: Unexpected end of input! Expecting a terminal of: ['__LPAR']

The above exception was the direct cause of the following exception:

Traceback (most recent call last):
  File ""irankfinder.py"", line 374, in <module>
  File ""irankfinder.py"", line 205, in launch
  File ""irankfinder.py"", line 197, in parse_file
Exception
",failed,0.34619832038879395,2025-05-23 03:53:58
TPDB_YES/recHanoi01_true-unreach-call_true-termination.c,ERROR,"[621133] Failed to execute script irankfinder
Traceback (most recent call last):
  File ""irankfinder.py"", line 190, in parse_file
  File ""genericparser/__init__.py"", line 109, in parse
  File ""genericparser/Parser_c.py"", line 21, in parse
Exception: b'Cannot use ""-eager-inline"" with a cyclic call hierarchy!\n'

The above exception was the direct cause of the following exception:

Traceback (most recent call last):
  File ""irankfinder.py"", line 374, in <module>
  File ""irankfinder.py"", line 205, in launch
  File ""irankfinder.py"", line 197, in parse_file
Exception
",failed,0.4525144100189209,2025-05-23 03:53:58
TPDB_YES/BallRajamani-SPIN2000-Fig1_false-unreach-call.c,ERROR,"[621147] Failed to execute script irankfinder
Traceback (most recent call last):
  File ""irankfinder.py"", line 190, in parse_file
  File ""genericparser/__init__.py"", line 109, in parse
  File ""genericparser/Parser_c.py"", line 21, in parse
Exception: b'Cannot use ""-eager-inline"" with a cyclic call hierarchy!\n'

The above exception was the direct cause of the following exception:

Traceback (most recent call last):
  File ""irankfinder.py"", line 374, in <module>
  File ""irankfinder.py"", line 205, in launch
  File ""irankfinder.py"", line 197, in parse_file
Exception
",failed,0.45424699783325195,2025-05-23 03:53:59
TPDB_YES/PastaA10.c,MAYBE,,success,1.6330838203430176,2025-05-23 03:54:00
TPDB_YES/svcomp_EvenOdd01_true-unreach-call_true-termination_modified.c,ERROR,"[621175] Failed to execute script irankfinder
Traceback (most recent call last):
  File ""irankfinder.py"", line 190, in parse_file
  File ""genericparser/__init__.py"", line 109, in parse
  File ""genericparser/Parser_c.py"", line 21, in parse
Exception: b'Cannot use ""-eager-inline"" with a cyclic call hierarchy!\n'

The above exception was the direct cause of the following exception:

Traceback (most recent call last):
  File ""irankfinder.py"", line 374, in <module>
  File ""irankfinder.py"", line 205, in launch
  File ""irankfinder.py"", line 197, in parse_file
Exception
",failed,0.4534316062927246,2025-05-23 03:54:01
TPDB_YES/svcomp_ex3b.c,MAYBE,,success,1.1380541324615479,2025-05-23 03:54:02
TPDB_YES/svcomp_easySum-alloca.c,ERROR,"[621203] Failed to execute script irankfinder
Traceback (most recent call last):
  File ""irankfinder.py"", line 190, in parse_file
  File ""genericparser/__init__.py"", line 109, in parse
  File ""genericparser/Parser_c.py"", line 25, in parse
  File ""genericparser/Parser_koat.py"", line 25, in parse_string
  File ""lark/lark.py"", line 197, in parse
  File ""lark/parser_frontends.py"", line 137, in parse
  File ""lark/parsers/xearley.py"", line 143, in parse
lark.common.ParseError: Unexpected end of input! Expecting a terminal of: ['__LPAR']

The above exception was the direct cause of the following exception:

Traceback (most recent call last):
  File ""irankfinder.py"", line 374, in <module>
  File ""irankfinder.py"", line 205, in launch
  File ""irankfinder.py"", line 197, in parse_file
Exception
",failed,0.4824051856994629,2025-05-23 03:54:02
TPDB_YES/svcomp_c.01-no-inv.c,MAYBE,,success,1.993539810180664,2025-05-23 03:54:04
TPDB_YES/PastaC9.c,MAYBE,,success,2.546532392501831,2025-05-23 03:54:07
TPDB_YES/nondet_ll_insert.c,ERROR,"[621244] Failed to execute script irankfinder
Traceback (most recent call last):
  File ""irankfinder.py"", line 190, in parse_file
  File ""genericparser/__init__.py"", line 109, in parse
  File ""genericparser/Parser_c.py"", line 25, in parse
  File ""genericparser/Parser_koat.py"", line 25, in parse_string
  File ""lark/lark.py"", line 197, in parse
  File ""lark/parser_frontends.py"", line 137, in parse
  File ""lark/parsers/xearley.py"", line 143, in parse
lark.common.ParseError: Unexpected end of input! Expecting a terminal of: ['__LPAR']

The above exception was the direct cause of the following exception:

Traceback (most recent call last):
  File ""irankfinder.py"", line 374, in <module>
  File ""irankfinder.py"", line 205, in launch
  File ""irankfinder.py"", line 197, in parse_file
Exception
",failed,0.47958898544311523,2025-05-23 03:54:07
TPDB_YES/fibo_2calls_2_false-unreach-call.c,ERROR,"[621257] Failed to execute script irankfinder
Traceback (most recent call last):
  File ""irankfinder.py"", line 190, in parse_file
  File ""genericparser/__init__.py"", line 109, in parse
  File ""genericparser/Parser_c.py"", line 21, in parse
Exception: b'Cannot use ""-eager-inline"" with a cyclic call hierarchy!\n'

The above exception was the direct cause of the following exception:

Traceback (most recent call last):
  File ""irankfinder.py"", line 374, in <module>
  File ""irankfinder.py"", line 205, in launch
  File ""irankfinder.py"", line 197, in parse_file
Exception
",failed,0.4578671455383301,2025-05-23 03:54:08
TPDB_YES/HeizmannHoenickeLeikePodelski-ATVA2013-Fig2_true-termination.c,MAYBE,,success,2.0380842685699463,2025-05-23 03:54:10
TPDB_YES/Masse-VMCAI2014-Fig1a_true-termination.c,MAYBE,,success,1.8821160793304443,2025-05-23 03:54:12
TPDB_YES/svcomp_a.01.c,MAYBE,,success,2.5228729248046875,2025-05-23 03:54:14
TPDB_YES/aviad_true-termination.c,YES,,success,2.9085731506347656,2025-05-23 03:54:17
TPDB_YES/Et3_true.c,ERROR,"[621327] Failed to execute script irankfinder
Traceback (most recent call last):
  File ""irankfinder.py"", line 190, in parse_file
  File ""genericparser/__init__.py"", line 109, in parse
  File ""genericparser/Parser_c.py"", line 21, in parse
Exception: b'Cannot use ""-eager-inline"" with a cyclic call hierarchy!\n'

The above exception was the direct cause of the following exception:

Traceback (most recent call last):
  File ""irankfinder.py"", line 374, in <module>
  File ""irankfinder.py"", line 205, in launch
  File ""irankfinder.py"", line 197, in parse_file
Exception
",failed,0.33321309089660645,2025-05-23 03:54:18
TPDB_YES/BradleyMannaSipma-CAV2005-Fig1_true-termination.c,MAYBE,,success,2.0487310886383057,2025-05-23 03:54:20
TPDB_YES/gcd01_true-unreach-call_true-termination.c,ERROR,"[621355] Failed to execute script irankfinder
Traceback (most recent call last):
  File ""irankfinder.py"", line 190, in parse_file
  File ""genericparser/__init__.py"", line 109, in parse
  File ""genericparser/Parser_c.py"", line 21, in parse
Exception: b'Cannot use ""-eager-inline"" with a cyclic call hierarchy!\n'

The above exception was the direct cause of the following exception:

Traceback (most recent call last):
  File ""irankfinder.py"", line 374, in <module>
  File ""irankfinder.py"", line 205, in launch
  File ""irankfinder.py"", line 197, in parse_file
Exception
",failed,0.4540669918060303,2025-05-23 03:54:20
TPDB_YES/TelAviv-Amir-Minimum_true-termination.c,MAYBE,,success,3.707763433456421,2025-05-23 03:54:24
TPDB_YES/diskperf_simpl1_true-unreach-call_true-termination.cil.c,ERROR,Execution timed out,failed,120,2025-05-23 03:56:24
TPDB_YES/svcomp_Urban-2013WST-Fig2-modified1000_true-alloca.c,ERROR,"[621398] Failed to execute script irankfinder
Traceback (most recent call last):
  File ""irankfinder.py"", line 190, in parse_file
  File ""genericparser/__init__.py"", line 109, in parse
  File ""genericparser/Parser_c.py"", line 25, in parse
  File ""genericparser/Parser_koat.py"", line 25, in parse_string
  File ""lark/lark.py"", line 197, in parse
  File ""lark/parser_frontends.py"", line 137, in parse
  File ""lark/parsers/xearley.py"", line 143, in parse
lark.common.ParseError: Unexpected end of input! Expecting a terminal of: ['__LPAR']

The above exception was the direct cause of the following exception:

Traceback (most recent call last):
  File ""irankfinder.py"", line 374, in <module>
  File ""irankfinder.py"", line 205, in launch
  File ""irankfinder.py"", line 197, in parse_file
Exception
",failed,0.4813969135284424,2025-05-23 03:56:24
TPDB_YES/svcomp_HarrisLalNoriRajamani-2010SAS-Fig1_true-alloca.c,ERROR,"[621411] Failed to execute script irankfinder
Traceback (most recent call last):
  File ""irankfinder.py"", line 190, in parse_file
  File ""genericparser/__init__.py"", line 109, in parse
  File ""genericparser/Parser_c.py"", line 25, in parse
  File ""genericparser/Parser_koat.py"", line 25, in parse_string
  File ""lark/lark.py"", line 197, in parse
  File ""lark/parser_frontends.py"", line 137, in parse
  File ""lark/parsers/xearley.py"", line 143, in parse
lark.common.ParseError: Unexpected end of input! Expecting a terminal of: ['__LPAR']

The above exception was the direct cause of the following exception:

Traceback (most recent call last):
  File ""irankfinder.py"", line 374, in <module>
  File ""irankfinder.py"", line 205, in launch
  File ""irankfinder.py"", line 197, in parse_file
Exception
",failed,0.4817826747894287,2025-05-23 03:56:25
TPDB_YES/cdaudio_simpl1_false-unreach-call_true-termination.cil.c,YES,,success,0.7483999729156494,2025-05-23 03:56:26
TPDB_YES/PastaC7.c,YES,,success,2.1240901947021484,2025-05-23 03:56:28
TPDB_YES/majority-noarray_true-termination.c,ERROR,Execution timed out,failed,120,2025-05-23 03:58:28
TPDB_YES/ChenFlurMukhopadhyay-SAS2012-Ex1.03_true-termination.c,YES,,success,1.6272187232971191,2025-05-23 03:58:29
TPDB_YES/LeeJonesBen-Amram-POPL2001-Ex5_true-termination.c,ERROR,"[621481] Failed to execute script irankfinder
Traceback (most recent call last):
  File ""irankfinder.py"", line 190, in parse_file
  File ""genericparser/__init__.py"", line 109, in parse
  File ""genericparser/Parser_c.py"", line 21, in parse
Exception: b'Cannot use ""-eager-inline"" with a cyclic call hierarchy!\n'

The above exception was the direct cause of the following exception:

Traceback (most recent call last):
  File ""irankfinder.py"", line 374, in <module>
  File ""irankfinder.py"", line 205, in launch
  File ""irankfinder.py"", line 197, in parse_file
Exception
",failed,0.4484524726867676,2025-05-23 03:58:30
TPDB_YES/svcomp_bubblesort_alloca.c,ERROR,"[621495] Failed to execute script irankfinder
Traceback (most recent call last):
  File ""irankfinder.py"", line 190, in parse_file
  File ""genericparser/__init__.py"", line 109, in parse
  File ""genericparser/Parser_c.py"", line 25, in parse
  File ""genericparser/Parser_koat.py"", line 25, in parse_string
  File ""lark/lark.py"", line 197, in parse
  File ""lark/parser_frontends.py"", line 137, in parse
  File ""lark/parsers/xearley.py"", line 143, in parse
lark.common.ParseError: Unexpected end of input! Expecting a terminal of: ['__LPAR']

The above exception was the direct cause of the following exception:

Traceback (most recent call last):
  File ""irankfinder.py"", line 374, in <module>
  File ""irankfinder.py"", line 205, in launch
  File ""irankfinder.py"", line 197, in parse_file
Exception
",failed,0.47385740280151367,2025-05-23 03:58:30
TPDB_YES/svcomp_flag.c,MAYBE,,success,2.1739718914031982,2025-05-23 03:58:33
TPDB_YES/svcomp_openbsd_cstrcmp_alloca.c,ERROR,"[621522] Failed to execute script irankfinder
Traceback (most recent call last):
  File ""irankfinder.py"", line 190, in parse_file
  File ""genericparser/__init__.py"", line 109, in parse
  File ""genericparser/Parser_c.py"", line 25, in parse
  File ""genericparser/Parser_koat.py"", line 25, in parse_string
  File ""lark/lark.py"", line 197, in parse
  File ""lark/parser_frontends.py"", line 137, in parse
  File ""lark/parsers/xearley.py"", line 143, in parse
lark.common.ParseError: Unexpected end of input! Expecting a terminal of: ['__LPAR']

The above exception was the direct cause of the following exception:

Traceback (most recent call last):
  File ""irankfinder.py"", line 374, in <module>
  File ""irankfinder.py"", line 205, in launch
  File ""irankfinder.py"", line 197, in parse_file
Exception
",failed,0.47879528999328613,2025-05-23 03:58:33
TPDB_YES/svcomp_b.15-alloca.c,ERROR,"[621535] Failed to execute script irankfinder
Traceback (most recent call last):
  File ""irankfinder.py"", line 190, in parse_file
  File ""genericparser/__init__.py"", line 109, in parse
  File ""genericparser/Parser_c.py"", line 25, in parse
  File ""genericparser/Parser_koat.py"", line 25, in parse_string
  File ""lark/lark.py"", line 197, in parse
  File ""lark/parser_frontends.py"", line 137, in parse
  File ""lark/parsers/xearley.py"", line 143, in parse
lark.common.ParseError: Unexpected end of input! Expecting a terminal of: ['__LPAR']

The above exception was the direct cause of the following exception:

Traceback (most recent call last):
  File ""irankfinder.py"", line 374, in <module>
  File ""irankfinder.py"", line 205, in launch
  File ""irankfinder.py"", line 197, in parse_file
Exception
",failed,0.3512125015258789,2025-05-23 03:58:33
TPDB_YES/svcomp_b.03-no-inv_assume.c,YES,,success,1.6448163986206055,2025-05-23 03:58:35
TPDB_YES/id_i10_o10_false-unreach-call.c,ERROR,"[621562] Failed to execute script irankfinder
Traceback (most recent call last):
  File ""irankfinder.py"", line 190, in parse_file
  File ""genericparser/__init__.py"", line 109, in parse
  File ""genericparser/Parser_c.py"", line 21, in parse
Exception: b'Cannot use ""-eager-inline"" with a cyclic call hierarchy!\n'

The above exception was the direct cause of the following exception:

Traceback (most recent call last):
  File ""irankfinder.py"", line 374, in <module>
  File ""irankfinder.py"", line 205, in launch
  File ""irankfinder.py"", line 197, in parse_file
Exception
",failed,0.3417329788208008,2025-05-23 03:58:35
TPDB_YES/svcomp_b.03_assume-alloca.c,ERROR,"[621576] Failed to execute script irankfinder
Traceback (most recent call last):
  File ""irankfinder.py"", line 190, in parse_file
  File ""genericparser/__init__.py"", line 109, in parse
  File ""genericparser/Parser_c.py"", line 25, in parse
  File ""genericparser/Parser_koat.py"", line 25, in parse_string
  File ""lark/lark.py"", line 197, in parse
  File ""lark/parser_frontends.py"", line 137, in parse
  File ""lark/parsers/xearley.py"", line 143, in parse
lark.common.ParseError: Unexpected end of input! Expecting a terminal of: ['__LPAR']

The above exception was the direct cause of the following exception:

Traceback (most recent call last):
  File ""irankfinder.py"", line 374, in <module>
  File ""irankfinder.py"", line 205, in launch
  File ""irankfinder.py"", line 197, in parse_file
Exception
",failed,0.47357177734375,2025-05-23 03:58:36
TPDB_YES/svcomp_Toulouse-BranchesToLoop_true-alloca.c,ERROR,"[621589] Failed to execute script irankfinder
Traceback (most recent call last):
  File ""irankfinder.py"", line 190, in parse_file
  File ""genericparser/__init__.py"", line 109, in parse
  File ""genericparser/Parser_c.py"", line 25, in parse
  File ""genericparser/Parser_koat.py"", line 25, in parse_string
  File ""lark/lark.py"", line 197, in parse
  File ""lark/parser_frontends.py"", line 137, in parse
  File ""lark/parsers/xearley.py"", line 143, in parse
lark.common.ParseError: Unexpected end of input! Expecting a terminal of: ['__LPAR']

The above exception was the direct cause of the following exception:

Traceback (most recent call last):
  File ""irankfinder.py"", line 374, in <module>
  File ""irankfinder.py"", line 205, in launch
  File ""irankfinder.py"", line 197, in parse_file
Exception
",failed,0.35198211669921875,2025-05-23 03:58:36
TPDB_YES/ChenFlurMukhopadhyay-SAS2012-Ex2.09_true-termination.c,MAYBE,,success,1.441253662109375,2025-05-23 03:58:38
TPDB_YES/Stockholm_true-termination.c,YES,,success,1.3815672397613525,2025-05-23 03:58:39
TPDB_YES/svcomp_java_Break-alloca.c,ERROR,"[621630] Failed to execute script irankfinder
Traceback (most recent call last):
  File ""irankfinder.py"", line 190, in parse_file
  File ""genericparser/__init__.py"", line 109, in parse
  File ""genericparser/Parser_c.py"", line 25, in parse
  File ""genericparser/Parser_koat.py"", line 25, in parse_string
  File ""lark/lark.py"", line 197, in parse
  File ""lark/parser_frontends.py"", line 137, in parse
  File ""lark/parsers/xearley.py"", line 143, in parse
lark.common.ParseError: Unexpected end of input! Expecting a terminal of: ['__LPAR']

The above exception was the direct cause of the following exception:

Traceback (most recent call last):
  File ""irankfinder.py"", line 374, in <module>
  File ""irankfinder.py"", line 205, in launch
  File ""irankfinder.py"", line 197, in parse_file
Exception
",failed,0.47391414642333984,2025-05-23 03:58:40
TPDB_YES/svcomp_a.05-alloca.c,ERROR,"[621643] Failed to execute script irankfinder
Traceback (most recent call last):
  File ""irankfinder.py"", line 190, in parse_file
  File ""genericparser/__init__.py"", line 109, in parse
  File ""genericparser/Parser_c.py"", line 25, in parse
  File ""genericparser/Parser_koat.py"", line 25, in parse_string
  File ""lark/lark.py"", line 197, in parse
  File ""lark/parser_frontends.py"", line 137, in parse
  File ""lark/parsers/xearley.py"", line 143, in parse
lark.common.ParseError: Unexpected end of input! Expecting a terminal of: ['__LPAR']

The above exception was the direct cause of the following exception:

Traceback (most recent call last):
  File ""irankfinder.py"", line 374, in <module>
  File ""irankfinder.py"", line 205, in launch
  File ""irankfinder.py"", line 197, in parse_file
Exception
",failed,0.48244786262512207,2025-05-23 03:58:40
TPDB_YES/svcomp_b.05.c,YES,,success,2.6720426082611084,2025-05-23 03:58:43
TPDB_YES/floppy_simpl3_false-unreach-call_true-termination.cil.c,ERROR,Execution timed out,failed,120,2025-05-23 04:00:43
TPDB_YES/NestedRecursion_2c_true-termination.c,ERROR,"[621685] Failed to execute script irankfinder
Traceback (most recent call last):
  File ""irankfinder.py"", line 190, in parse_file
  File ""genericparser/__init__.py"", line 109, in parse
  File ""genericparser/Parser_c.py"", line 21, in parse
Exception: b'Cannot use ""-eager-inline"" with a cyclic call hierarchy!\n'

The above exception was the direct cause of the following exception:

Traceback (most recent call last):
  File ""irankfinder.py"", line 374, in <module>
  File ""irankfinder.py"", line 205, in launch
  File ""irankfinder.py"", line 197, in parse_file
Exception
",failed,0.4574921131134033,2025-05-23 04:00:43
TPDB_YES/standard_password_true-unreach-call_ground.c,MAYBE,,success,4.5260701179504395,2025-05-23 04:00:48
TPDB_YES/MinusMin.c,YES,,success,2.1709303855895996,2025-05-23 04:00:50
TPDB_YES/ChenFlurMukhopadhyay-SAS2012-Ex3.08_true-termination.c,MAYBE,,success,1.9793806076049805,2025-05-23 04:00:52
TPDB_YES/svcomp_c.01_assume-alloca.c,ERROR,"[621741] Failed to execute script irankfinder
Traceback (most recent call last):
  File ""irankfinder.py"", line 190, in parse_file
  File ""genericparser/__init__.py"", line 109, in parse
  File ""genericparser/Parser_c.py"", line 25, in parse
  File ""genericparser/Parser_koat.py"", line 25, in parse_string
  File ""lark/lark.py"", line 197, in parse
  File ""lark/parser_frontends.py"", line 137, in parse
  File ""lark/parsers/xearley.py"", line 143, in parse
lark.common.ParseError: Unexpected end of input! Expecting a terminal of: ['__LPAR']

The above exception was the direct cause of the following exception:

Traceback (most recent call last):
  File ""irankfinder.py"", line 374, in <module>
  File ""irankfinder.py"", line 205, in launch
  File ""irankfinder.py"", line 197, in parse_file
Exception
",failed,0.35118556022644043,2025-05-23 04:00:52
TPDB_YES/LeikeHeizmann-TACAS2014-Ex8_true-termination.c,MAYBE,,success,1.9216811656951904,2025-05-23 04:00:54
TPDB_YES/svcomp_openbsd_cstrnlen_alloca.c,ERROR,"[621768] Failed to execute script irankfinder
Traceback (most recent call last):
  File ""irankfinder.py"", line 190, in parse_file
  File ""genericparser/__init__.py"", line 109, in parse
  File ""genericparser/Parser_c.py"", line 25, in parse
  File ""genericparser/Parser_koat.py"", line 25, in parse_string
  File ""lark/lark.py"", line 197, in parse
  File ""lark/parser_frontends.py"", line 137, in parse
  File ""lark/parsers/xearley.py"", line 143, in parse
lark.common.ParseError: Unexpected end of input! Expecting a terminal of: ['__LPAR']

The above exception was the direct cause of the following exception:

Traceback (most recent call last):
  File ""irankfinder.py"", line 374, in <module>
  File ""irankfinder.py"", line 205, in launch
  File ""irankfinder.py"", line 197, in parse_file
Exception
",failed,0.3547089099884033,2025-05-23 04:00:55
TPDB_YES/svcomp_b.12.c,MAYBE,,success,3.2825818061828613,2025-05-23 04:00:58
TPDB_YES/s3_clnt_1_false-unreach-call.cil.c,ERROR,Execution timed out,failed,120,2025-05-23 04:02:58
TPDB_YES/ex2.c,ERROR,"[621810] Failed to execute script irankfinder
Traceback (most recent call last):
  File ""irankfinder.py"", line 190, in parse_file
  File ""genericparser/__init__.py"", line 109, in parse
  File ""genericparser/Parser_c.py"", line 21, in parse
Exception: b'Cannot use ""-eager-inline"" with a cyclic call hierarchy!\n'

The above exception was the direct cause of the following exception:

Traceback (most recent call last):
  File ""irankfinder.py"", line 374, in <module>
  File ""irankfinder.py"", line 205, in launch
  File ""irankfinder.py"", line 197, in parse_file
Exception
",failed,0.45907020568847656,2025-05-23 04:02:59
TPDB_YES/svcomp_cstrcspn_true-termination.c,ERROR,"[621824] Failed to execute script irankfinder
Traceback (most recent call last):
  File ""irankfinder.py"", line 190, in parse_file
  File ""genericparser/__init__.py"", line 109, in parse
  File ""genericparser/Parser_c.py"", line 25, in parse
  File ""genericparser/Parser_koat.py"", line 25, in parse_string
  File ""lark/lark.py"", line 197, in parse
  File ""lark/parser_frontends.py"", line 137, in parse
  File ""lark/parsers/xearley.py"", line 143, in parse
lark.common.ParseError: Unexpected end of input! Expecting a terminal of: ['__LPAR']

The above exception was the direct cause of the following exception:

Traceback (most recent call last):
  File ""irankfinder.py"", line 374, in <module>
  File ""irankfinder.py"", line 205, in launch
  File ""irankfinder.py"", line 197, in parse_file
Exception
",failed,0.3545241355895996,2025-05-23 04:02:59
TPDB_YES/LeeJonesBen-Amram-POPL2001-Ex2_true-termination.c,ERROR,"[621837] Failed to execute script irankfinder
Traceback (most recent call last):
  File ""irankfinder.py"", line 190, in parse_file
  File ""genericparser/__init__.py"", line 109, in parse
  File ""genericparser/Parser_c.py"", line 21, in parse
Exception: b'Cannot use ""-eager-inline"" with a cyclic call hierarchy!\n'

The above exception was the direct cause of the following exception:

Traceback (most recent call last):
  File ""irankfinder.py"", line 374, in <module>
  File ""irankfinder.py"", line 205, in launch
  File ""irankfinder.py"", line 197, in parse_file
Exception
",failed,0.4451720714569092,2025-05-23 04:02:59
TPDB_YES/NoriSharma-FSE2013-Fig8_true-termination.c,MAYBE,,success,2.945737361907959,2025-05-23 04:03:02
TPDB_YES/GopanReps-CAV2006-Fig1a_true-termination.c.c,MAYBE,,success,1.6127634048461914,2025-05-23 04:03:04
TPDB_YES/svcomp_c.03.c,MAYBE,,success,1.9623162746429443,2025-05-23 04:03:06
TPDB_YES/svcomp_gcd1_true-alloca.c,ERROR,"[621893] Failed to execute script irankfinder
Traceback (most recent call last):
  File ""irankfinder.py"", line 190, in parse_file
  File ""genericparser/__init__.py"", line 109, in parse
  File ""genericparser/Parser_c.py"", line 25, in parse
  File ""genericparser/Parser_koat.py"", line 25, in parse_string
  File ""lark/lark.py"", line 197, in parse
  File ""lark/parser_frontends.py"", line 137, in parse
  File ""lark/parsers/xearley.py"", line 143, in parse
lark.common.ParseError: Unexpected end of input! Expecting a terminal of: ['__LPAR']

The above exception was the direct cause of the following exception:

Traceback (most recent call last):
  File ""irankfinder.py"", line 374, in <module>
  File ""irankfinder.py"", line 205, in launch
  File ""irankfinder.py"", line 197, in parse_file
Exception
",failed,0.4870035648345947,2025-05-23 04:03:07
TPDB_YES/HeizmannHoenickeLeikePodelski-ATVA2013-Fig9_true-termination.c,MAYBE,,success,1.5210072994232178,2025-05-23 04:03:08
TPDB_YES/Arrays03-ValueRestictsIndex_true-termination.c,MAYBE,,success,1.8290977478027344,2025-05-23 04:03:10
TPDB_YES/Parallel_true-termination.c,MAYBE,,success,2.1422088146209717,2025-05-23 04:03:12
TPDB_YES/Overflow.c,YES,,success,0.8667590618133545,2025-05-23 04:03:13
TPDB_YES/MinusBuiltIn.c,YES,,success,1.127243995666504,2025-05-23 04:03:14
TPDB_YES/svcomp_lis_alloca.c,ERROR,"[621976] Failed to execute script irankfinder
Traceback (most recent call last):
  File ""irankfinder.py"", line 190, in parse_file
  File ""genericparser/__init__.py"", line 109, in parse
  File ""genericparser/Parser_c.py"", line 25, in parse
  File ""genericparser/Parser_koat.py"", line 25, in parse_string
  File ""lark/lark.py"", line 197, in parse
  File ""lark/parser_frontends.py"", line 137, in parse
  File ""lark/parsers/xearley.py"", line 143, in parse
lark.common.ParseError: Unexpected end of input! Expecting a terminal of: ['__LPAR']

The above exception was the direct cause of the following exception:

Traceback (most recent call last):
  File ""irankfinder.py"", line 374, in <module>
  File ""irankfinder.py"", line 205, in launch
  File ""irankfinder.py"", line 197, in parse_file
Exception
",failed,0.3492753505706787,2025-05-23 04:03:14
TPDB_YES/nondet_ll_search_last_zero.c,ERROR,"[621989] Failed to execute script irankfinder
Traceback (most recent call last):
  File ""irankfinder.py"", line 190, in parse_file
  File ""genericparser/__init__.py"", line 109, in parse
  File ""genericparser/Parser_c.py"", line 25, in parse
  File ""genericparser/Parser_koat.py"", line 25, in parse_string
  File ""lark/lark.py"", line 197, in parse
  File ""lark/parser_frontends.py"", line 137, in parse
  File ""lark/parsers/xearley.py"", line 143, in parse
lark.common.ParseError: Unexpected end of input! Expecting a terminal of: ['__LPAR']

The above exception was the direct cause of the following exception:

Traceback (most recent call last):
  File ""irankfinder.py"", line 374, in <module>
  File ""irankfinder.py"", line 205, in launch
  File ""irankfinder.py"", line 197, in parse_file
Exception
",failed,0.35749340057373047,2025-05-23 04:03:15
TPDB_YES/PastaA9.c,YES,,success,1.1914913654327393,2025-05-23 04:03:16
TPDB_YES/Gothenburg_true-termination.c,MAYBE,,success,2.1533355712890625,2025-05-23 04:03:18
TPDB_YES/PodelskiRybalchenko-TACAS2011-Fig2_true-termination.c,MAYBE,,success,1.4938836097717285,2025-05-23 04:03:20
TPDB_YES/svcomp_flag-alloca.c,ERROR,"[622044] Failed to execute script irankfinder
Traceback (most recent call last):
  File ""irankfinder.py"", line 190, in parse_file
  File ""genericparser/__init__.py"", line 109, in parse
  File ""genericparser/Parser_c.py"", line 25, in parse
  File ""genericparser/Parser_koat.py"", line 25, in parse_string
  File ""lark/lark.py"", line 197, in parse
  File ""lark/parser_frontends.py"", line 137, in parse
  File ""lark/parsers/xearley.py"", line 143, in parse
lark.common.ParseError: Unexpected end of input! Expecting a terminal of: ['__LPAR']

The above exception was the direct cause of the following exception:

Traceback (most recent call last):
  File ""irankfinder.py"", line 374, in <module>
  File ""irankfinder.py"", line 205, in launch
  File ""irankfinder.py"", line 197, in parse_file
Exception
",failed,0.3502929210662842,2025-05-23 04:03:20
TPDB_YES/Toulouse-BranchesToLoop_true-termination.c,MAYBE,,success,1.5763306617736816,2025-05-23 04:03:22
TPDB_YES/svcomp_cstrpbrk_true-termination.c,ERROR,"[622071] Failed to execute script irankfinder
Traceback (most recent call last):
  File ""irankfinder.py"", line 190, in parse_file
  File ""genericparser/__init__.py"", line 109, in parse
  File ""genericparser/Parser_c.py"", line 25, in parse
  File ""genericparser/Parser_koat.py"", line 25, in parse_string
  File ""lark/lark.py"", line 197, in parse
  File ""lark/parser_frontends.py"", line 137, in parse
  File ""lark/parsers/xearley.py"", line 143, in parse
lark.common.ParseError: Unexpected end of input! Expecting a terminal of: ['__LPAR']

The above exception was the direct cause of the following exception:

Traceback (most recent call last):
  File ""irankfinder.py"", line 374, in <module>
  File ""irankfinder.py"", line 205, in launch
  File ""irankfinder.py"", line 197, in parse_file
Exception
",failed,0.3459150791168213,2025-05-23 04:03:22
TPDB_YES/svcomp_c.02-alloca.c,ERROR,"[622084] Failed to execute script irankfinder
Traceback (most recent call last):
  File ""irankfinder.py"", line 190, in parse_file
  File ""genericparser/__init__.py"", line 109, in parse
  File ""genericparser/Parser_c.py"", line 25, in parse
  File ""genericparser/Parser_koat.py"", line 25, in parse_string
  File ""lark/lark.py"", line 197, in parse
  File ""lark/parser_frontends.py"", line 137, in parse
  File ""lark/parsers/xearley.py"", line 143, in parse
lark.common.ParseError: Unexpected end of input! Expecting a terminal of: ['__LPAR']

The above exception was the direct cause of the following exception:

Traceback (most recent call last):
  File ""irankfinder.py"", line 374, in <module>
  File ""irankfinder.py"", line 205, in launch
  File ""irankfinder.py"", line 197, in parse_file
Exception
",failed,0.48094773292541504,2025-05-23 04:03:22
TPDB_YES/AliasDarteFeautrierGonnord-SAS2010-random1d_true-termination.c,YES,,success,1.9498083591461182,2025-05-23 04:03:24
TPDB_YES/svcomp_fermat-alloca.c,ERROR,"[622111] Failed to execute script irankfinder
Traceback (most recent call last):
  File ""irankfinder.py"", line 190, in parse_file
  File ""genericparser/__init__.py"", line 109, in parse
  File ""genericparser/Parser_c.py"", line 25, in parse
  File ""genericparser/Parser_koat.py"", line 25, in parse_string
  File ""lark/lark.py"", line 197, in parse
  File ""lark/parser_frontends.py"", line 137, in parse
  File ""lark/parsers/xearley.py"", line 143, in parse
lark.common.ParseError: Unexpected end of input! Expecting a terminal of: ['__LPAR']

The above exception was the direct cause of the following exception:

Traceback (most recent call last):
  File ""irankfinder.py"", line 374, in <module>
  File ""irankfinder.py"", line 205, in launch
  File ""irankfinder.py"", line 197, in parse_file
Exception
",failed,0.48326992988586426,2025-05-23 04:03:25
TPDB_YES/Ben-Amram-LMCS2010-Ex2.3_true-termination.c,MAYBE,,success,3.1522622108459473,2025-05-23 04:03:28
TPDB_YES/AliasDarteFeautrierGonnord-SAS2010-speedFails4_true-termination.c,MAYBE,,success,1.7484350204467773,2025-05-23 04:03:30
TPDB_YES/svcomp_stroeder1_alloca.c,ERROR,"[622152] Failed to execute script irankfinder
Traceback (most recent call last):
  File ""irankfinder.py"", line 190, in parse_file
  File ""genericparser/__init__.py"", line 109, in parse
  File ""genericparser/Parser_c.py"", line 25, in parse
  File ""genericparser/Parser_koat.py"", line 25, in parse_string
  File ""lark/lark.py"", line 197, in parse
  File ""lark/parser_frontends.py"", line 137, in parse
  File ""lark/parsers/xearley.py"", line 143, in parse
lark.common.ParseError: Unexpected end of input! Expecting a terminal of: ['__LPAR']

The above exception was the direct cause of the following exception:

Traceback (most recent call last):
  File ""irankfinder.py"", line 374, in <module>
  File ""irankfinder.py"", line 205, in launch
  File ""irankfinder.py"", line 197, in parse_file
Exception
",failed,0.48284459114074707,2025-05-23 04:03:30
TPDB_YES/AliasDarteFeautrierGonnord-SAS2010-exmini_true-termination.c,YES,,success,2.1776955127716064,2025-05-23 04:03:33
TPDB_YES/svcomp_openbsd_cmemset_alloca.c,ERROR,"[622179] Failed to execute script irankfinder
Traceback (most recent call last):
  File ""irankfinder.py"", line 190, in parse_file
  File ""genericparser/__init__.py"", line 109, in parse
  File ""genericparser/Parser_c.py"", line 25, in parse
  File ""genericparser/Parser_koat.py"", line 25, in parse_string
  File ""lark/lark.py"", line 197, in parse
  File ""lark/parser_frontends.py"", line 137, in parse
  File ""lark/parsers/xearley.py"", line 143, in parse
lark.common.ParseError: Unexpected end of input! Expecting a terminal of: ['__LPAR']

The above exception was the direct cause of the following exception:

Traceback (most recent call last):
  File ""irankfinder.py"", line 374, in <module>
  File ""irankfinder.py"", line 205, in launch
  File ""irankfinder.py"", line 197, in parse_file
Exception
",failed,0.4727895259857178,2025-05-23 04:03:33
TPDB_YES/PastaA5.c,YES,,success,1.062244176864624,2025-05-23 04:03:34
TPDB_YES/svcomp_java_Continue1.c,MAYBE,,success,1.3813209533691406,2025-05-23 04:03:35
TPDB_YES/easy2_true-termination.c,YES,,success,1.6239783763885498,2025-05-23 04:03:37
TPDB_YES/svcomp_diff_alloca.c,ERROR,"[622234] Failed to execute script irankfinder
Traceback (most recent call last):
  File ""irankfinder.py"", line 190, in parse_file
  File ""genericparser/__init__.py"", line 109, in parse
  File ""genericparser/Parser_c.py"", line 25, in parse
  File ""genericparser/Parser_koat.py"", line 25, in parse_string
  File ""lark/lark.py"", line 197, in parse
  File ""lark/parser_frontends.py"", line 137, in parse
  File ""lark/parsers/xearley.py"", line 143, in parse
lark.common.ParseError: Unexpected end of input! Expecting a terminal of: ['__LPAR']

The above exception was the direct cause of the following exception:

Traceback (most recent call last):
  File ""irankfinder.py"", line 374, in <module>
  File ""irankfinder.py"", line 205, in launch
  File ""irankfinder.py"", line 197, in parse_file
Exception
",failed,0.475618839263916,2025-05-23 04:03:38
TPDB_YES/ChenFlurMukhopadhyay-SAS2012-Ex2.07_true-termination.c,MAYBE,,success,1.7570538520812988,2025-05-23 04:03:39
TPDB_YES/svcomp_b.16.c,MAYBE,,success,3.1418330669403076,2025-05-23 04:03:43
TPDB_YES/McCarthy91_Iteration_true-termination.c,MAYBE,,success,2.0880768299102783,2025-05-23 04:03:45
TPDB_YES/nondet_ll_delete.c,ERROR,"[622289] Failed to execute script irankfinder
Traceback (most recent call last):
  File ""irankfinder.py"", line 190, in parse_file
  File ""genericparser/__init__.py"", line 109, in parse
  File ""genericparser/Parser_c.py"", line 25, in parse
  File ""genericparser/Parser_koat.py"", line 25, in parse_string
  File ""lark/lark.py"", line 197, in parse
  File ""lark/parser_frontends.py"", line 137, in parse
  File ""lark/parsers/xearley.py"", line 143, in parse
lark.common.ParseError: Unexpected end of input! Expecting a terminal of: ['__LPAR']

The above exception was the direct cause of the following exception:

Traceback (most recent call last):
  File ""irankfinder.py"", line 374, in <module>
  File ""irankfinder.py"", line 205, in launch
  File ""irankfinder.py"", line 197, in parse_file
Exception
",failed,0.35631418228149414,2025-05-23 04:03:45
TPDB_YES/LeikeHeizmann-TACAS2014-Ex1_true-termination.c,YES,,success,1.563159704208374,2025-05-23 04:03:47
TPDB_YES/CookSeeZuleger-TACAS2013-Fig7a_true-termination.c,MAYBE,,success,4.367448568344116,2025-05-23 04:03:51
